Workbook

Sheet 1. Hướng dẫn
B2: LỘ TRÌNH CHINH PHỤC JLPT N5 TRONG 90 NGÀY
B3: Bám sát giáo trình MINNA NO NIHONGO I (bài 1–25) · 104 Hiragana · 104 Katakana · 45 bộ thủ · 103 Kanji · 112 mẫu ngữ pháp · 350 từ vựng có mẹo nhớ
B5: 👉 NGÀY BẮT ĐẦU HỌC | C5: 46266 | D5: ◀ Chỉ cần sửa ô vàng này, cả file tự cập nhật
B6: Ngày thi dự kiến | C6: =$C$5+89 -> 46355 | D6: Ngày bắt đầu cộng 89 ngày
B9: MỖI NGÀY CHỈ CẦN 2 BƯỚC
B10: Bước 1 | C10: Mở sheet '2. Lộ trình tổng quan', tìm dòng của hôm nay. Dòng này cho biết nhanh: hôm nay học Minna bài mấy, Kanji nào, bộ thủ nào, mấy mẫu ngữ pháp, mấy từ mới.
B11: Bước 2 | C11: Mở sheet chi tiết tương ứng (3, 4, 5 hoặc 6), tìm khối màu của ngày đó. Ở đó có 4–6 đầu việc kèm số phút, nội dung đầy đủ: từng chữ Kanji có âm On/Kun và mẹo nhớ, từng mẫu ngữ pháp có câu ví dụ, từng từ vựng có mẹo nhớ. Xong việc nào tick 'Xong' việc đó.
B12: Lưu ý | C12: Bạn CHỈ tick ở sheet chi tiết. Cột tiến độ ở sheet tổng quan tự chạy theo, không phải tick hai lần.
B14: CẦN CHUẨN BỊ GÌ
B15: Sách chính | C15: Minna no Nihongo I — bản Honsatsu (sách chính) và bản dịch–giải thích ngữ pháp tiếng Việt. Nên có thêm CD hoặc file nghe đi kèm.
B16: Sách bài tập | C16: Minna no Nihongo I — Hyōjun Mondaishū (標準問題集) để làm bài tập và phần nghe sau mỗi bài.
B17: Dụng cụ | C17: Vở kẻ ô vuông để luyện viết Kanji, một cuốn sổ tay nhỏ ghi lỗi sai, bút chì 2B.
B18: Ứng dụng | C18: Anki hoặc Quizlet để ôn từ vựng theo phương pháp lặp lại ngắt quãng.
B20: BA GIAI ĐOẠN
B21: Ngày 1–14 · Bảng chữ cái | C21: Tuần 1 Hiragana, tuần 2 Katakana. Chưa mở Minna vội. Mỗi âm đều có mẹo nhớ hình dáng ở sheet 7.
B22: Ngày 15–77 · Minna bài 1–25 | C22: Mỗi bài học trong 2 ngày (riêng bài 14, 17, 19, 20 khó hơn nên được 3 ngày). Mỗi ngày: 1 bộ thủ + 2 Kanji + 2 mẫu ngữ pháp + 7 từ mới + 20 phút nghe/đọc. Chủ Nhật hằng tuần là ngày ôn, không học bài mới.
B23: Ngày 78–90 · Tổng ôn | C23: Ôn lại toàn bộ, hai đề thi thử full bấm giờ vào ngày 84 và 88. Ngày 90 nghỉ ngơi.
B25: HỌC TỪ VỰNG KIỂU NÀO CHO NHỚ
B26: 1. Ưu tiên âm Hán Việt | C26: Đây là lợi thế lớn nhất của người Việt. 先生 = TIÊN SINH, 会社員 = HỘI XÃ VIÊN, 図書館 = ĐỒ THƯ QUÁN. Biết âm Hán Việt là đoán được nghĩa hàng trăm từ chưa từng học.
B27: 2. Tách chữ ra thành bộ thủ | C27: 休 = 亻(người) tựa 木(cây) → nghỉ mát. 明 = 日(mặt trời) + 月(mặt trăng) → sáng. Cách này nhớ lâu gấp nhiều lần học vẹt từng nét.
B28: 3. Học theo cụm, đừng học chữ lẻ | C28: Đừng học 電 một mình. Học luôn 電車 (tàu điện), 電話 (điện thoại), 電気 (điện). Một chữ kéo theo ba từ.
B29: 4. Học theo cặp trái nghĩa | C29: 上手↔下手, 大きい↔小さい, 安い↔高い, 押します↔引きます. Não ghi nhớ theo cặp tốt hơn nhiều so với ghi nhớ đơn lẻ.
B30: 5. Với từ thuần kana | C30: Dùng liên tưởng âm thanh tiếng Việt: ねこ (mèo) — 'nê cô'; おなか (bụng) — 'ô, na ca'. Mỗi từ trong file đều đã có sẵn một mẹo ở cột 'Mẹo nhớ'.
B31: 6. Ôn ngắt quãng | C31: Từ mới hôm nay phải được gặp lại sau 1 ngày, 3 ngày, 1 tuần. Đó chính là lý do có ngày ôn Chủ Nhật và cột 'Ngày học' trong mọi sheet tra cứu.
B33: VÌ SAO PHẢI HỌC BỘ THỦ
B34: Bộ thủ là gì | C34: Là những mảnh ghép nhỏ tạo nên chữ Kanji. Ví dụ 語 (ngôn ngữ) = 言 (lời nói) + 五 + 口 (miệng).
B35: Lợi ích | C35: Mọi chữ có bộ 言 đều liên quan đến nói năng: 話 nói chuyện, 語 ngôn ngữ, 読 đọc, 記 ghi chép. Học 45 bộ là mở khóa được hàng nghìn chữ.
B36: Cách học | C36: Mỗi ngày ở giai đoạn 2 chỉ học 1 bộ, mất 10 phút. Bảng đầy đủ ở sheet '8. Bộ thủ 45'.
B38: MẸO ĐỂ KHÔNG BỎ CUỘC
B39: Quy tắc 2 ngày | C39: Được nghỉ 1 ngày, nhưng không bao giờ nghỉ 2 ngày liên tiếp.
B40: Ngày quá bận | C40: Làm 'phiên bản rút gọn': chỉ làm việc Kanji và Từ vựng của hôm đó (khoảng 40 phút). Có mặt quan trọng hơn hoàn hảo.
B41: Phải viết tay | C41: Kanji chỉ nhớ được khi viết tay. Nhìn màn hình tạo cảm giác đã thuộc nhưng vào phòng thi sẽ quên.
B42: Điểm chuẩn N5 | C42: Tổng ≥ 80/180, VÀ mỗi phần ≥ 19/60. Nghĩa là không được bỏ hẳn phần Nghe.
B44: MÃ MÀU
B45: Vàng nhạt | C45: Giai đoạn 1 — Bảng chữ cái
B46: Xanh lá nhạt | C46: Giai đoạn 2 — Minna no Nihongo I
B47: Vàng đậm | C47: Ngày ôn tập cuối tuần (Chủ Nhật)
B48: Hồng nhạt | C48: Giai đoạn 3 — Tổng ôn
B49: Cam | C49: Ngày thi thử (ngày 84 và 88)
B50: Xanh lá đậm | C50: Việc bạn đã tick 'Xong'
...

Sheet 2. Lộ trình tổng quan
A1: LỘ TRÌNH TỔNG QUAN 90 NGÀY — xem nhanh ở đây, làm chi tiết ở sheet 3–6
A2: Ngày | B2: Ngày dự kiến | C2: Tuần | D2: Giai đoạn | E2: Minna | F2: Nội dung chính hôm nay | G2: Kanji | H2: Bộ thủ | I2: Ngữ pháp | J2: Từ mới | K2: Nghe/Đọc | L2: Phút | M2: Đã xong | N2: Tiến độ | O2: Ghi chú
A3: 1 | B3: ='1. Hướng dẫn'!$C$5+0 -> 46266 | C3: 1 | D3: Kana | E3: — | F3: Hiragana: 10 âm mới (あ → こ) | G3: — | H3: — | I3: — | J3: 2 từ | K3: Nghe | L3: 90 | M3: =COUNTIF('3. Chi tiết N1-14'!$D$4:$D$8,"Xong")&"/5" -> 0/5 | N3: =COUNTIF('3. Chi tiết N1-14'!$D$4:$D$8,"Xong")/5 -> 0
A4: 2 | B4: ='1. Hướng dẫn'!$C$5+1 -> 46267 | C4: 1 | D4: Kana | E4: — | F4: Hiragana: 9 âm mới (さ → て) | G4: — | H4: — | I4: — | J4: 2 từ | K4: Nghe | L4: 90 | M4: =COUNTIF('3. Chi tiết N1-14'!$D$11:$D$15,"Xong")&"/5" -> 0/5 | N4: =COUNTIF('3. Chi tiết N1-14'!$D$11:$D$15,"Xong")/5 -> 0
A5: 3 | B5: ='1. Hướng dẫn'!$C$5+2 -> 46268 | C5: 1 | D5: Kana | E5: — | F5: Hiragana: 9 âm mới (と → ふ) | G5: — | H5: — | I5: — | J5: 2 từ | K5: Nghe | L5: 90 | M5: =COUNTIF('3. Chi tiết N1-14'!$D$18:$D$22,"Xong")&"/5" -> 0/5 | N5: =COUNTIF('3. Chi tiết N1-14'!$D$18:$D$22,"Xong")/5 -> 0
A6: 4 | B6: ='1. Hướng dẫn'!$C$5+3 -> 46269 | C6: 1 | D6: Kana | E6: — | F6: Hiragana: 9 âm mới (へ → ゆ) | G6: — | H6: — | I6: — | J6: 2 từ | K6: Nghe | L6: 90 | M6: =COUNTIF('3. Chi tiết N1-14'!$D$25:$D$29,"Xong")&"/5" -> 0/5 | N6: =COUNTIF('3. Chi tiết N1-14'!$D$25:$D$29,"Xong")/5 -> 0
A7: 5 | B7: ='1. Hướng dẫn'!$C$5+4 -> 46270 | C7: 1 | D7: Kana | E7: — | F7: Hiragana: 9 âm mới (よ → ん) | G7: — | H7: — | I7: — | J7: 2 từ | K7: Nghe | L7: 90 | M7: =COUNTIF('3. Chi tiết N1-14'!$D$32:$D$36,"Xong")&"/5" -> 0/5 | N7: =COUNTIF('3. Chi tiết N1-14'!$D$32:$D$36,"Xong")/5 -> 0
A8: 6 | B8: ='1. Hướng dẫn'!$C$5+5 -> 46271 | C8: 1 | D8: Kana | E8: — | F8: Hiragana: âm đục, âm bán đục và âm ghép | G8: — | H8: — | I8: — | J8: 2 từ | K8: Nghe | L8: 90 | M8: =COUNTIF('3. Chi tiết N1-14'!$D$39:$D$43,"Xong")&"/5" -> 0/5 | N8: =COUNTIF('3. Chi tiết N1-14'!$D$39:$D$43,"Xong")/5 -> 0
A9: 7 | B9: ='1. Hướng dẫn'!$C$5+6 -> 46272 | C9: 1 | D9: Kana | E9: — | F9: Ôn tập & kiểm tra toàn bộ Hiragana | G9: — | H9: — | I9: — | J9: 2 từ | K9: Nghe | L9: 85 | M9: =COUNTIF('3. Chi tiết N1-14'!$D$46:$D$50,"Xong")&"/5" -> 0/5 | N9: =COUNTIF('3. Chi tiết N1-14'!$D$46:$D$50,"Xong")/5 -> 0
A10: 8 | B10: ='1. Hướng dẫn'!$C$5+7 -> 46273 | C10: 2 | D10: Kana | E10: — | F10: Katakana: 10 âm mới (ア → コ) | G10: — | H10: — | I10: — | J10: 2 từ | K10: Nghe | L10: 90 | M10: =COUNTIF('3. Chi tiết N1-14'!$D$53:$D$57,"Xong")&"/5" -> 0/5 | N10: =COUNTIF('3. Chi tiết N1-14'!$D$53:$D$57,"Xong")/5 -> 0
A11: 9 | B11: ='1. Hướng dẫn'!$C$5+8 -> 46274 | C11: 2 | D11: Kana | E11: — | F11: Katakana: 9 âm mới (サ → テ) | G11: — | H11: — | I11: — | J11: 2 từ | K11: Nghe | L11: 90 | M11: =COUNTIF('3. Chi tiết N1-14'!$D$60:$D$64,"Xong")&"/5" -> 0/5 | N11: =COUNTIF('3. Chi tiết N1-14'!$D$60:$D$64,"Xong")/5 -> 0
A12: 10 | B12: ='1. Hướng dẫn'!$C$5+9 -> 46275 | C12: 2 | D12: Kana | E12: — | F12: Katakana: 9 âm mới (ト → フ) | G12: — | H12: — | I12: — | J12: 2 từ | K12: Nghe | L12: 90 | M12: =COUNTIF('3. Chi tiết N1-14'!$D$67:$D$71,"Xong")&"/5" -> 0/5 | N12: =COUNTIF('3. Chi tiết N1-14'!$D$67:$D$71,"Xong")/5 -> 0
A13: 11 | B13: ='1. Hướng dẫn'!$C$5+10 -> 46276 | C13: 2 | D13: Kana | E13: — | F13: Katakana: 9 âm mới (ヘ → ユ) | G13: — | H13: — | I13: — | J13: 2 từ | K13: Nghe | L13: 90 | M13: =COUNTIF('3. Chi tiết N1-14'!$D$74:$D$78,"Xong")&"/5" -> 0/5 | N13: =COUNTIF('3. Chi tiết N1-14'!$D$74:$D$78,"Xong")/5 -> 0
A14: 12 | B14: ='1. Hướng dẫn'!$C$5+11 -> 46277 | C14: 2 | D14: Kana | E14: — | F14: Katakana: 9 âm mới (ヨ → ン) | G14: — | H14: — | I14: — | J14: 2 từ | K14: Nghe | L14: 90 | M14: =COUNTIF('3. Chi tiết N1-14'!$D$81:$D$85,"Xong")&"/5" -> 0/5 | N14: =COUNTIF('3. Chi tiết N1-14'!$D$81:$D$85,"Xong")/5 -> 0
A15: 13 | B15: ='1. Hướng dẫn'!$C$5+12 -> 46278 | C15: 2 | D15: Kana | E15: — | F15: Katakana: âm đục, âm bán đục và âm ghép | G15: — | H15: — | I15: — | J15: 2 từ | K15: Nghe | L15: 90 | M15: =COUNTIF('3. Chi tiết N1-14'!$D$88:$D$92,"Xong")&"/5" -> 0/5 | N15: =COUNTIF('3. Chi tiết N1-14'!$D$88:$D$92,"Xong")/5 -> 0
A16: 14 | B16: ='1. Hướng dẫn'!$C$5+13 -> 46279 | C16: 2 | D16: Kana | E16: — | F16: Ôn tập & kiểm tra toàn bộ Katakana | G16: — | H16: — | I16: — | J16: 2 từ | K16: Nghe | L16: 85 | M16: =COUNTIF('3. Chi tiết N1-14'!$D$95:$D$99,"Xong")&"/5" -> 0/5 | N16: =COUNTIF('3. Chi tiết N1-14'!$D$95:$D$99,"Xong")/5 -> 0
A17: 15 | B17: ='1. Hướng dẫn'!$C$5+14 -> 46280 | C17: 3 | D17: Minna | E17: Bài 1 (1/2) | F17: Chào hỏi & Giới thiệu bản thân | G17: 日、一 | H17: 人 / 亻 | I17: 3 mẫu | J17: 7 từ | K17: Nghe | L17: 100 | M17: =COUNTIF('4. Chi tiết N15-45'!$D$4:$D$9,"Xong")&"/6" -> 0/6 | N17: =COUNTIF('4. Chi tiết N15-45'!$D$4:$D$9,"Xong")/6 -> 0
A18: 16 | B18: ='1. Hướng dẫn'!$C$5+15 -> 46281 | C18: 3 | D18: Minna | E18: Bài 1 (2/2) | F18: Chào hỏi & Giới thiệu bản thân | G18: 国、会 | H18: 口 | I18: 2 mẫu | J18: 7 từ | K18: Nghe | L18: 100 | M18: =COUNTIF('4. Chi tiết N15-45'!$D$12:$D$17,"Xong")&"/6" -> 0/6 | N18: =COUNTIF('4. Chi tiết N15-45'!$D$12:$D$17,"Xong")/6 -> 0
A19: 17 | B19: ='1. Hướng dẫn'!$C$5+16 -> 46282 | C19: 3 | D19: Minna | E19: Bài 2 (1/2) | F19: これ・それ・あれ — Chỉ đồ vật | G19: 人、年 | H19: 日 | I19: 3 mẫu | J19: 7 từ | K19: Đọc | L19: 100 | M19: =COUNTIF('4. Chi tiết N15-45'!$D$20:$D$25,"Xong")&"/6" -> 0/6 | N19: =COUNTIF('4. Chi tiết N15-45'!$D$20:$D$25,"Xong")/6 -> 0
A20: 18 | B20: ='1. Hướng dẫn'!$C$5+17 -> 46283 | C20: 3 | D20: Minna | E20: Bài 2 (2/2) | F20: これ・それ・あれ — Chỉ đồ vật | G20: 大、十 | H20: 月 | I20: 2 mẫu | J20: 7 từ | K20: Nghe | L20: 100 | M20: =COUNTIF('4. Chi tiết N15-45'!$D$28:$D$33,"Xong")&"/6" -> 0/6 | N20: =COUNTIF('4. Chi tiết N15-45'!$D$28:$D$33,"Xong")/6 -> 0
A21: 19 | B21: ='1. Hướng dẫn'!$C$5+18 -> 46284 | C21: 3 | D21: Minna | E21: Bài 3 (1/2) | F21: ここ・そこ・あそこ — Chỉ nơi chốn | G21: 二、本 | H21: 木 | I21: 3 mẫu | J21: 7 từ | K21: Đọc | L21: 100 | M21: =COUNTIF('4. Chi tiết N15-45'!$D$36:$D$41,"Xong")&"/6" -> 0/6 | N21: =COUNTIF('4. Chi tiết N15-45'!$D$36:$D$41,"Xong")/6 -> 0
A22: 20 | B22: ='1. Hướng dẫn'!$C$5+19 -> 46285 | C22: 3 | D22: Minna | E22: Bài 3 (2/2) | F22: ここ・そこ・あそこ — Chỉ nơi chốn | G22: 中、長 | H22: 水 / 氵 | I22: 2 mẫu | J22: 7 từ | K22: Nghe | L22: 100 | M22: =COUNTIF('4. Chi tiết N15-45'!$D$44:$D$49,"Xong")&"/6" -> 0/6 | N22: =COUNTIF('4. Chi tiết N15-45'!$D$44:$D$49,"Xong")/6 -> 0
A23: 21 | B23: ='1. Hướng dẫn'!$C$5+20 -> 46286 | C23: 3 | D23: Minna | E23: Ôn bài 1–3 | F23: Ôn tập tuần 3 — Minna bài 1–3 | G23: Ôn tuần | H23: Ôn tuần | I23: 練習B・C | J23: Ôn tuần | K23: Nghe + Đọc | L23: 105 | M23: =COUNTIF('4. Chi tiết N15-45'!$D$52:$D$56,"Xong")&"/5" -> 0/5 | N23: =COUNTIF('4. Chi tiết N15-45'!$D$52:$D$56,"Xong")/5 -> 0
A24: 22 | B24: ='1. Hướng dẫn'!$C$5+21 -> 46287 | C24: 4 | D24: Minna | E24: Bài 4 (1/2) | F24: Giờ giấc & Thì của động từ | G24: 出、三 | H24: 火 / 灬 | I24: 3 mẫu | J24: 7 từ | K24: Nghe | L24: 100 | M24: =COUNTIF('4. Chi tiết N15-45'!$D$59:$D$64,"Xong")&"/6" -> 0/6 | N24: =COUNTIF('4. Chi tiết N15-45'!$D$59:$D$64,"Xong")/6 -> 0
A25: 23 | B25: ='1. Hướng dẫn'!$C$5+22 -> 46288 | C25: 4 | D25: Minna | E25: Bài 4 (2/2) | F25: Giờ giấc & Thì của động từ | G25: 時、行 | H25: 土 | I25: 3 mẫu | J25: 7 từ | K25: Đọc | L25: 100 | M25: =COUNTIF('4. Chi tiết N15-45'!$D$67:$D$72,"Xong")&"/6" -> 0/6 | N25: =COUNTIF('4. Chi tiết N15-45'!$D$67:$D$72,"Xong")/6 -> 0
A26: 24 | B26: ='1. Hướng dẫn'!$C$5+23 -> 46289 | C26: 4 | D26: Minna | E26: Bài 5 (1/2) | F26: Đi lại — Phương tiện & Điểm đến | G26: 社、見 | H26: 金 | I26: 3 mẫu | J26: 7 từ | K26: Nghe | L26: 100 | M26: =COUNTIF('4. Chi tiết N15-45'!$D$75:$D$80,"Xong")&"/6" -> 0/6 | N26: =COUNTIF('4. Chi tiết N15-45'!$D$75:$D$80,"Xong")/6 -> 0
A27: 25 | B27: ='1. Hướng dẫn'!$C$5+24 -> 46290 | C27: 4 | D27: Minna | E27: Bài 5 (2/2) | F27: Đi lại — Phương tiện & Điểm đến | G27: 月、分 | H27: 女 | I27: 2 mẫu | J27: 7 từ | K27: Đọc | L27: 100 | M27: =COUNTIF('4. Chi tiết N15-45'!$D$83:$D$88,"Xong")&"/6" -> 0/6 | N27: =COUNTIF('4. Chi tiết N15-45'!$D$83:$D$88,"Xong")/6 -> 0
A28: 26 | B28: ='1. Hướng dẫn'!$C$5+25 -> 46291 | C28: 4 | D28: Minna | E28: Bài 6 (1/2) | F28: Tân ngữ を & Rủ rê | G28: 後、前 | H28: 子 | I28: 3 mẫu | J28: 7 từ | K28: Nghe | L28: 100 | M28: =COUNTIF('4. Chi tiết N15-45'!$D$91:$D$96,"Xong")&"/6" -> 0/6 | N28: =COUNTIF('4. Chi tiết N15-45'!$D$91:$D$96,"Xong")/6 -> 0
A29: 27 | B29: ='1. Hướng dẫn'!$C$5+26 -> 46292 | C29: 4 | D29: Minna | E29: Bài 6 (2/2) | F29: Tân ngữ を & Rủ rê | G29: 生、五 | H29: 心 / 忄 | I29: 2 mẫu | J29: 7 từ | K29: Nghe | L29: 100 | M29: =COUNTIF('4. Chi tiết N15-45'!$D$99:$D$104,"Xong")&"/6" -> 0/6 | N29: =COUNTIF('4. Chi tiết N15-45'!$D$99:$D$104,"Xong")/6 -> 0
A30: 28 | B30: ='1. Hướng dẫn'!$C$5+27 -> 46293 | C30: 4 | D30: Minna | E30: Ôn bài 4–6 | F30: Ôn tập tuần 4 — Minna bài 4–6 | G30: Ôn tuần | H30: Ôn tuần | I30: 練習B・C | J30: Ôn tuần | K30: Nghe + Đọc | L30: 105 | M30: =COUNTIF('4. Chi tiết N15-45'!$D$107:$D$111,"Xong")&"/5" -> 0/5 | N30: =COUNTIF('4. Chi tiết N15-45'!$D$107:$D$111,"Xong")/5 -> 0
A31: 29 | B31: ='1. Hướng dẫn'!$C$5+28 -> 46294 | C31: 5 | D31: Minna | E31: Bài 7 (1/2) | F31: Cho & Nhận, Công cụ で | G31: 間、上 | H31: 手 / 扌 | I31: 3 mẫu | J31: 7 từ | K31: Đọc | L31: 100 | M31: =COUNTIF('4. Chi tiết N15-45'!$D$114:$D$119,"Xong")&"/6" -> 0/6 | N31: =COUNTIF('4. Chi tiết N15-45'!$D$114:$D$119,"Xong")/6 -> 0
A32: 30 | B32: ='1. Hướng dẫn'!$C$5+29 -> 46295 | C32: 5 | D32: Minna | E32: Bài 7 (2/2) | F32: Cho & Nhận, Công cụ で | G32: 東、四 | H32: 目 | I32: 2 mẫu | J32: 7 từ | K32: Nghe | L32: 100 | M32: =COUNTIF('4. Chi tiết N15-45'!$D$122:$D$127,"Xong")&"/6" -> 0/6 | N32: =COUNTIF('4. Chi tiết N15-45'!$D$122:$D$127,"Xong")/6 -> 0
A33: 31 | B33: ='1. Hướng dẫn'!$C$5+30 -> 46296 | C33: 5 | D33: Minna | E33: Bài 8 (1/2) | F33: Tính từ | G33: 今、新 | H33: 耳 | I33: 3 mẫu | J33: 7 từ | K33: Đọc | L33: 100 | M33: =COUNTIF('4. Chi tiết N15-45'!$D$130:$D$135,"Xong")&"/6" -> 0/6 | N33: =COUNTIF('4. Chi tiết N15-45'!$D$130:$D$135,"Xong")/6 -> 0
A34: 32 | B34: ='1. Hướng dẫn'!$C$5+31 -> 46297 | C34: 5 | D34: Minna | E34: Bài 8 (2/2) | F34: Tính từ | G34: 金、九 | H34: 足 / ⻊ | I34: 2 mẫu | J34: 7 từ | K34: Nghe | L34: 100 | M34: =COUNTIF('4. Chi tiết N15-45'!$D$138:$D$143,"Xong")&"/6" -> 0/6 | N34: =COUNTIF('4. Chi tiết N15-45'!$D$138:$D$143,"Xong")/6 -> 0
A35: 33 | B35: ='1. Hướng dẫn'!$C$5+32 -> 46298 | C35: 5 | D35: Minna | E35: Bài 9 (1/2) | F35: Thích / Giỏi / Có & Lý do から | G35: 入、立 | H35: 言 / 訁 | I35: 3 mẫu | J35: 7 từ | K35: Nghe | L35: 100 | M35: =COUNTIF('4. Chi tiết N15-45'!$D$146:$D$151,"Xong")&"/6" -> 0/6 | N35: =COUNTIF('4. Chi tiết N15-45'!$D$146:$D$151,"Xong")/6 -> 0
A36: 34 | B36: ='1. Hướng dẫn'!$C$5+33 -> 46299 | C36: 5 | D36: Minna | E36: Bài 9 (2/2) | F36: Thích / Giỏi / Có & Lý do から | G36: 手、学 | H36: 車 | I36: 2 mẫu | J36: 7 từ | K36: Nghe | L36: 100 | M36: =COUNTIF('4. Chi tiết N15-45'!$D$154:$D$159,"Xong")&"/6" -> 0/6 | N36: =COUNTIF('4. Chi tiết N15-45'!$D$154:$D$159,"Xong")/6 -> 0
A37: 35 | B37: ='1. Hướng dẫn'!$C$5+34 -> 46300 | C37: 5 | D37: Minna | E37: Ôn bài 7–9 | F37: Ôn tập tuần 5 — Minna bài 7–9 | G37: Ôn tuần | H37: Ôn tuần | I37: 練習B・C | J37: Ôn tuần | K37: Nghe + Đọc | L37: 105 | M37: =COUNTIF('4. Chi tiết N15-45'!$D$162:$D$166,"Xong")&"/5" -> 0/5 | N37: =COUNTIF('4. Chi tiết N15-45'!$D$162:$D$166,"Xong")/5 -> 0
A38: 36 | B38: ='1. Hướng dẫn'!$C$5+35 -> 46301 | C38: 6 | D38: Minna | E38: Bài 10 (1/2) | F38: Tồn tại — あります / います & Vị trí | G38: 高、円 | H38: 門 | I38: 2 mẫu | J38: 7 từ | K38: Nghe | L38: 100 | M38: =COUNTIF('4. Chi tiết N15-45'!$D$169:$D$174,"Xong")&"/6" -> 0/6 | N38: =COUNTIF('4. Chi tiết N15-45'!$D$169:$D$174,"Xong")/6 -> 0
A39: 37 | B39: ='1. Hướng dẫn'!$C$5+36 -> 46302 | C39: 6 | D39: Minna | E39: Bài 10 (2/2) | F39: Tồn tại — あります / います & Vị trí | G39: 子、目 | H39: 食 / 飠 | I39: 2 mẫu | J39: 7 từ | K39: Đọc | L39: 100 | M39: =COUNTIF('4. Chi tiết N15-45'!$D$177:$D$182,"Xong")&"/6" -> 0/6 | N39: =COUNTIF('4. Chi tiết N15-45'!$D$177:$D$182,"Xong")/6 -> 0
A40: 38 | B40: ='1. Hướng dẫn'!$C$5+37 -> 46303 | C40: 6 | D40: Minna | E40: Bài 11 (1/2) | F40: Số đếm & Lượng từ | G40: 外、言 | H40: 魚 | I40: 3 mẫu | J40: 7 từ | K40: Nghe | L40: 100 | M40: =COUNTIF('4. Chi tiết N15-45'!$D$185:$D$190,"Xong")&"/6" -> 0/6 | N40: =COUNTIF('4. Chi tiết N15-45'!$D$185:$D$190,"Xong")/6 -> 0
...

Sheet 3. Chi tiết N1-14
A1: GIAI ĐOẠN 1 · NGÀY 1–14 · BẢNG CHỮ CÁI
A2: Mục | B2: Việc cần làm hôm nay | C2: Phút | D2: Trạng thái | E2: Ghi chú
A3: NGÀY 1 · Tuần 1 · Hiragana: 10 âm mới (あ → こ) 〔90 phút · 5 việc〕
A4: あ Học chữ mới | B4: Học 10 âm: あ (a) い (i) う (u) え (e) お (o) か (ka) き (ki) く (ku) け (ke) こ (ko). Xem thứ tự nét trước khi viết. Mẹo nhớ hình dáng từng chữ có ở sheet '7. Bảng chữ cái'. | C4: 25 | D4: Chưa học
A5: ✎ Viết tay | B5: Viết mỗi âm 10 lần trên giấy kẻ ô, vừa viết vừa đọc to. | C5: 25 | D5: Chưa học
A6: ? Tự kiểm tra | B6: Che romaji, nhìn chữ đọc âm. Rồi che chữ, nghe âm viết chữ. | C6: 15 | D6: Chưa học
A7: 語 Từ vựng | B7: Học 2 từ mới: おはようございます (chào buổi sáng) ・ こんにちは (xin chào) | C7: 15 | D7: Chưa học
A8: 耳 Nghe | B8: Nghe phát âm chuẩn các âm hôm nay 3 lượt, nhắc theo. | C8: 10 | D8: Chưa học
A10: NGÀY 2 · Tuần 1 · Hiragana: 9 âm mới (さ → て) 〔90 phút · 5 việc〕
A11: あ Học chữ mới | B11: Học 9 âm: さ (sa) し (shi) す (su) せ (se) そ (so) た (ta) ち (chi) つ (tsu) て (te). Xem thứ tự nét trước khi viết. Mẹo nhớ hình dáng từng chữ có ở sheet '7. Bảng chữ cái'. | C11: 25 | D11: Chưa học
A12: ✎ Viết tay | B12: Viết mỗi âm 10 lần trên giấy kẻ ô, vừa viết vừa đọc to. | C12: 25 | D12: Chưa học
A13: ? Tự kiểm tra | B13: Che romaji, nhìn chữ đọc âm. Rồi che chữ, nghe âm viết chữ. | C13: 15 | D13: Chưa học
A14: 語 Từ vựng | B14: Học 2 từ mới: こんばんは (chào buổi tối) ・ さようなら (tạm biệt) | C14: 15 | D14: Chưa học
A15: 耳 Nghe | B15: Nghe phát âm chuẩn các âm hôm nay 3 lượt, nhắc theo. | C15: 10 | D15: Chưa học
A17: NGÀY 3 · Tuần 1 · Hiragana: 9 âm mới (と → ふ) 〔90 phút · 5 việc〕
A18: あ Học chữ mới | B18: Học 9 âm: と (to) な (na) に (ni) ぬ (nu) ね (ne) の (no) は (ha) ひ (hi) ふ (fu). Xem thứ tự nét trước khi viết. Mẹo nhớ hình dáng từng chữ có ở sheet '7. Bảng chữ cái'. | C18: 25 | D18: Chưa học
A19: ✎ Viết tay | B19: Viết mỗi âm 10 lần trên giấy kẻ ô, vừa viết vừa đọc to. | C19: 25 | D19: Chưa học
A20: ? Tự kiểm tra | B20: Che romaji, nhìn chữ đọc âm. Rồi che chữ, nghe âm viết chữ. | C20: 15 | D20: Chưa học
A21: 語 Từ vựng | B21: Học 2 từ mới: ありがとうございます (cảm ơn) ・ どういたしまして (không có gì) | C21: 15 | D21: Chưa học
A22: 耳 Nghe | B22: Nghe phát âm chuẩn các âm hôm nay 3 lượt, nhắc theo. | C22: 10 | D22: Chưa học
A24: NGÀY 4 · Tuần 1 · Hiragana: 9 âm mới (へ → ゆ) 〔90 phút · 5 việc〕
A25: あ Học chữ mới | B25: Học 9 âm: へ (he) ほ (ho) ま (ma) み (mi) む (mu) め (me) も (mo) や (ya) ゆ (yu). Xem thứ tự nét trước khi viết. Mẹo nhớ hình dáng từng chữ có ở sheet '7. Bảng chữ cái'. | C25: 25 | D25: Chưa học
A26: ✎ Viết tay | B26: Viết mỗi âm 10 lần trên giấy kẻ ô, vừa viết vừa đọc to. | C26: 25 | D26: Chưa học
A27: ? Tự kiểm tra | B27: Che romaji, nhìn chữ đọc âm. Rồi che chữ, nghe âm viết chữ. | C27: 15 | D27: Chưa học
A28: 語 Từ vựng | B28: Học 2 từ mới: すみません (xin lỗi) ・ ごめんなさい (xin lỗi, thân mật) | C28: 15 | D28: Chưa học
A29: 耳 Nghe | B29: Nghe phát âm chuẩn các âm hôm nay 3 lượt, nhắc theo. | C29: 10 | D29: Chưa học
A31: NGÀY 5 · Tuần 1 · Hiragana: 9 âm mới (よ → ん) 〔90 phút · 5 việc〕
A32: あ Học chữ mới | B32: Học 9 âm: よ (yo) ら (ra) り (ri) る (ru) れ (re) ろ (ro) わ (wa) を (wo) ん (n). Xem thứ tự nét trước khi viết. Mẹo nhớ hình dáng từng chữ có ở sheet '7. Bảng chữ cái'. | C32: 25 | D32: Chưa học
A33: ✎ Viết tay | B33: Viết mỗi âm 10 lần trên giấy kẻ ô, vừa viết vừa đọc to. | C33: 25 | D33: Chưa học
A34: ? Tự kiểm tra | B34: Che romaji, nhìn chữ đọc âm. Rồi che chữ, nghe âm viết chữ. | C34: 15 | D34: Chưa học
A35: 語 Từ vựng | B35: Học 2 từ mới: はじめまして (rất vui được gặp) ・ どうぞよろしく (mong được giúp đỡ) | C35: 15 | D35: Chưa học
A36: 耳 Nghe | B36: Nghe phát âm chuẩn các âm hôm nay 3 lượt, nhắc theo. | C36: 10 | D36: Chưa học
A38: NGÀY 6 · Tuần 1 · Hiragana: âm đục, âm bán đục và âm ghép 〔90 phút · 5 việc〕
A39: ゛ Âm đục | B39: Học 25 âm đục/bán đục. Quy tắc: thêm dấu " thành âm đục (か→が), dấu ° thành bán đục (は→ぱ). Xem sheet '7. Bảng chữ cái'. | C39: 25 | D39: Chưa học
A40: ゃ Âm ghép | B40: Học 33 âm ghép. Quy tắc: chữ hàng い + や/ゆ/よ viết nhỏ (き+ゃ = きゃ). | C40: 25 | D40: Chưa học
A41: ✎ Viết tay | B41: Viết mỗi âm 5 lần, đọc to khi viết. | C41: 20 | D41: Chưa học
A42: 語 Từ vựng | B42: Học 2 từ mới: はい (vâng) ・ いいえ (không) ・ わかりました (tôi hiểu rồi) | C42: 10 | D42: Chưa học
A43: 耳 Nghe | B43: Luyện phân biệt âm trong và âm đục: か/が, た/だ, は/ば/ぱ. | C43: 10 | D43: Chưa học
A45: NGÀY 7 · Tuần 1 · Ôn tập & kiểm tra toàn bộ Hiragana 〔85 phút · 5 việc〕
A46: ? Kiểm tra | B46: Lấy giấy trắng, viết lại toàn bộ 104 âm Hiragana mà KHÔNG nhìn bảng. Đối chiếu, khoanh tròn âm sai. | C46: 25 | D46: Chưa học
...

Sheet 4. Chi tiết N15-45
A1: GIAI ĐOẠN 2A · NGÀY 15–45 · MINNA BÀI 1–13
A2: Mục | B2: Việc cần làm hôm nay | C2: Phút | D2: Trạng thái | E2: Ghi chú
A3: NGÀY 15 · Tuần 3 · Minna Bài 1 (1/2) · Chào hỏi & Giới thiệu bản thân 〔100 phút · 6 việc〕
A4: ◐ Khởi động | B4: Ôn nhanh nội dung hôm qua: đọc lại Kanji và mẫu ngữ pháp cũ, không nhìn đáp án. | C4: 5 | D4: Chưa học
A5: 部 Bộ thủ | B5: Bộ 人 / 亻 (ひと / にんべん) = Người Mẹo nhớ: 亻 đứng bên trái = dáng người đứng nghiêng Kanji chứa bộ này: 人・休・何・今 | C5: 10 | D5: Chưa học
A6: 漢 Kanji | B6: Học 2 chữ. Mỗi chữ viết tay 10 lần đúng thứ tự nét. • 日 [NHẬT] Ngày, mặt trời — On: ニチ・ジツ / Kun: ひ・か (4 nét) Từ ghép: 日本 (にほん) Nhật Bản ・ 今日 (きょう) hôm nay ・ 毎日 (まいにち) hằng ngày Mẹo: Ô vuông có một gạch ở giữa = mặt trời có chấm đen. Mặt trời mọc một lần → một NGÀY. • 一 [NHẤT] Một — On: イチ・イツ / Kun: ひと(つ) (1 nét) Từ ghép: 一つ (ひとつ) một cái ・ 一人 (ひとり) một người ・ 一月 (いちがつ) tháng Một Mẹo: Một nét ngang = số 1. Dễ nhất trong 103 chữ, nhưng chú ý 一人 đọc bất quy tắc là ひとり. | C6: 20 | D6: Chưa học
A7: 文 Ngữ pháp | B7: Minna bài 1 (1/2) — Chào hỏi & Giới thiệu bản thân • N1 は N2 です (N1 là N2. は đọc là 'wa' khi làm trợ từ chủ đề.) Ví dụ: わたしは グエンです。 = Tôi là Nguyễn. • N1 は N2 じゃ ありません (N1 không phải là N2. Văn viết dùng では ありません.) Ví dụ: わたしは 学生じゃ ありません。 = Tôi không phải là học sinh. • N1 は N2 ですか (N1 có phải là N2 không? Thêm か cuối câu là thành câu hỏi.) Ví dụ: ミラーさんは アメリカ人ですか。 = Anh Miller là người Mỹ phải không? → Làm 練習A của bài 1 trong sách, mỗi mẫu tự đặt 3 câu. | C7: 25 | D7: Chưa học
A8: 語 Từ vựng | B8: Từ mới Minna bài 1: • わたし（私） = Tôi Mẹo: Kanji 私 = 禾 (lúa) + ム (riêng) → phần lúa riêng của mình = TÔI. • あなた = Bạn, anh/chị Mẹo: A-NA-TA nghe gần như 'anh ta' — người đối diện mình. • せんせい（先生） = Giáo viên Mẹo: Âm Hán Việt TIÊN SINH = người sinh ra trước, đi trước ta → thầy cô. • がくせい（学生） = Học sinh, sinh viên Mẹo: HỌC SINH — 学 (học) + 生 (sinh). Đọc thẳng âm Hán Việt là ra. • かいしゃいん（会社員） = Nhân viên công ty Mẹo: HỘI XÃ VIÊN = 会 (hội) + 社 (xã) + 員 (viên). • いしゃ（医者） = Bác sĩ Mẹo: Y GIẢ = người làm nghề y. 者 (giả) = người, gặp lại ở 学者, 記者. • ぎんこういん（銀行員） = Nhân viên ngân hàng Mẹo: NGÂN HÀNH VIÊN. 銀行 = ngân hàng, thêm 員 thành người làm ở đó. → Đối chiếu thêm với mục 語彙 của bài 1 trong sách để bổ sung. | C8: 20 | D8: Chưa học
A9: 耳 Nghe | B9: Mở CD Minna no Nihongo bài đang học, phần 会話. Nghe 3 lượt: lượt 1 chỉ nghe, lượt 2 nhìn script, lượt 3 nghe và nhắc theo. | C9: 20 | D9: Chưa học
A11: NGÀY 16 · Tuần 3 · Minna Bài 1 (2/2) · Chào hỏi & Giới thiệu bản thân 〔100 phút · 6 việc〕
A12: ◐ Khởi động | B12: Ôn nhanh nội dung hôm qua: đọc lại Kanji và mẫu ngữ pháp cũ, không nhìn đáp án. | C12: 5 | D12: Chưa học
A13: 部 Bộ thủ | B13: Bộ 口 (くち) = Miệng, cái lỗ Mẹo nhớ: Ô vuông nhỏ = cái miệng đang mở Kanji chứa bộ này: 口・名・右・古 | C13: 10 | D13: Chưa học
A14: 漢 Kanji | B14: Học 2 chữ. Mỗi chữ viết tay 10 lần đúng thứ tự nét. • 国 [QUỐC] Đất nước — On: コク / Kun: くに (8 nét) Từ ghép: 外国 (がいこく) nước ngoài ・ 国語 (こくご) quốc ngữ ・ 中国 (ちゅうごく) Trung Quốc Mẹo: Bộ 囗 (vòng vây, biên giới) bao lấy 玉 (ngọc quý) = lãnh thổ có biên giới bảo vệ báu vật → QUỐC GIA. • 会 [HỘI] Gặp gỡ, hội họp — On: カイ / Kun: あ(う) (6 nét) Từ ghép: 会社 (かいしゃ) công ty ・ 会います (あいます) gặp ・ 会話 (かいわ) hội thoại Mẹo: Mái nhà 人 che bên trên, nhiều người tụ lại bên dưới = cuộc HỘI HỌP. | C14: 20 | D14: Chưa học
A15: 文 Ngữ pháp | B15: Minna bài 1 (2/2) — Chào hỏi & Giới thiệu bản thân • N も (N cũng. Thay thế vị trí của は.) Ví dụ: わたしも ベトナム人です。 = Tôi cũng là người Việt Nam. • N1 の N2 (N2 thuộc về / của N1.) Ví dụ: わたしは ABCの 社員です。 = Tôi là nhân viên của công ty ABC. → Làm 練習A của bài 1 trong sách, mỗi mẫu tự đặt 3 câu. | C15: 25 | D15: Chưa học
A16: 語 Từ vựng | B16: Từ mới Minna bài 1: • だいがく（大学） = Đại học Mẹo: ĐẠI HỌC — chuẩn âm Hán Việt, không cần mẹo gì thêm. • なまえ（名前） = Tên Mẹo: DANH TIỀN = cái danh đặt phía trước. Nhớ 名 (danh) + 前 (tiền/trước). • だれ / どなた = Ai (どなた lịch sự hơn) Mẹo: DA-RE: 'Đá rê' bóng cho AI? どなた dùng khi hỏi người trên. • 〜さん = Hậu tố lịch sự sau tên người Mẹo: Không bao giờ dùng さん cho chính mình. • 〜じん（〜人） = Người nước ~ Mẹo: ベトナム人 = người Việt. 人 đọc じん khi đứng sau tên nước. • はじめまして = Rất hân hạnh được gặp Mẹo: Chỉ nói MỘT LẦN duy nhất khi gặp lần đầu. • どうぞ よろしく = Mong được giúp đỡ Mẹo: Câu chốt sau khi giới thiệu tên. Lịch sự hơn: よろしく おねがいします。 → Đối chiếu thêm với mục 語彙 của bài 1 trong sách để bổ sung. | C16: 20 | D16: Chưa học
A17: 耳 Nghe | B17: Shadowing 15 phút: bật lại 会話 hôm qua, nói đuổi theo băng, không nhìn script. | C17: 20 | D17: Chưa học
A19: NGÀY 17 · Tuần 3 · Minna Bài 2 (1/2) · これ・それ・あれ — Chỉ đồ vật 〔100 phút · 6 việc〕
A20: ◐ Khởi động | B20: Ôn nhanh nội dung hôm qua: đọc lại Kanji và mẫu ngữ pháp cũ, không nhìn đáp án. | C20: 5 | D20: Chưa học
A21: 部 Bộ thủ | B21: Bộ 日 (ひ / にちへん) = Mặt trời, ngày Mẹo nhớ: Ô vuông có gạch giữa = mặt trời Kanji chứa bộ này: 日・時・明・早 | C21: 10 | D21: Chưa học
A22: 漢 Kanji | B22: Học 2 chữ. Mỗi chữ viết tay 10 lần đúng thứ tự nét. • 人 [NHÂN] Người — On: ジン・ニン / Kun: ひと (2 nét) Từ ghép: 日本人 (にほんじん) người Nhật ・ 一人 (ひとり) một người ・ 人口 (じんこう) dân số Mẹo: Hai nét như hai chân đang bước = dáng NGƯỜI đi. Đuôi 〜人 gắn tên nước = người nước đó. • 年 [NIÊN] Năm — On: ネン / Kun: とし (6 nét) Từ ghép: 今年 (ことし) năm nay ・ 去年 (きょねん) năm ngoái ・ 一年 (いちねん) một năm Mẹo: Hình cây lúa trĩu hạt. Lúa chín một vụ = trôi qua một NĂM. | C22: 20 | D22: Chưa học
A23: 文 Ngữ pháp | B23: Minna bài 2 (1/2) — これ・それ・あれ — Chỉ đồ vật • これ / それ / あれ (Cái này (gần tôi) / cái đó (gần bạn) / cái kia (xa cả hai). Đứng một mình như danh từ.) Ví dụ: これは 本です。 = Cái này là quyển sách. • この N / その N / あの N (N này / N đó / N kia. Bắt buộc phải có danh từ đi sau.) Ví dụ: この 本は わたしのです。 = Quyển sách này là của tôi. • そうです / そうじゃ ありません (Đúng vậy / Không phải vậy. Dùng trả lời câu hỏi có–không.) Ví dụ: はい、そうです。 = Vâng, đúng vậy. → Làm 練習A của bài 2 trong sách, mỗi mẫu tự đặt 3 câu. | C23: 25 | D23: Chưa học
A24: 語 Từ vựng | B24: Từ mới Minna bài 2: • ほん（本） = Sách Mẹo: 本 = gốc cây (木 thêm vạch ở rễ) → gốc tri thức → SÁCH. • じしょ（辞書） = Từ điển Mẹo: TỪ THƯ = sách chứa từ. 書 (thư) = viết/sách. • ざっし（雑誌） = Tạp chí Mẹo: TẠP CHÍ — âm Hán Việt gần như y hệt tiếng Việt. • しんぶん（新聞） = Báo Mẹo: TÂN VĂN = tin mới nghe được. 新 (mới) + 聞 (nghe). • てちょう（手帳） = Sổ tay Mẹo: THỦ TRƯỚNG = cuốn sổ cầm trên TAY (手). • めいし（名刺） = Danh thiếp Mẹo: DANH THÍCH = tấm ghi tên. 名 (danh) đã học ở 名前. • かぎ（鍵） = Chìa khóa Mẹo: KA-GI: 'cà ghi' — cắm chìa vào ổ nghe 'cạch'. → Đối chiếu thêm với mục 語彙 của bài 2 trong sách để bổ sung. | C24: 20 | D24: Chưa học
A25: 読 Đọc | B25: Làm phần 読み物 hoặc 練習C của bài đang học. Đọc to thành tiếng ít nhất 1 lượt. | C25: 20 | D25: Chưa học
A27: NGÀY 18 · Tuần 3 · Minna Bài 2 (2/2) · これ・それ・あれ — Chỉ đồ vật 〔100 phút · 6 việc〕
A28: ◐ Khởi động | B28: Ôn nhanh nội dung hôm qua: đọc lại Kanji và mẫu ngữ pháp cũ, không nhìn đáp án. | C28: 5 | D28: Chưa học
A29: 部 Bộ thủ | B29: Bộ 月 (つき / にくづき) = Mặt trăng, tháng, thân thể Mẹo nhớ: Trăng khuyết; khi chỉ cơ thể đọc là にくづき Kanji chứa bộ này: 月・前・服 | C29: 10 | D29: Chưa học
A30: 漢 Kanji | B30: Học 2 chữ. Mỗi chữ viết tay 10 lần đúng thứ tự nét. • 大 [ĐẠI] To, lớn — On: ダイ・タイ / Kun: おお(きい) (3 nét) Từ ghép: 大学 (だいがく) đại học ・ 大きい (おおきい) to ・ 大人 (おとな) người lớn Mẹo: Người 人 dang rộng hai tay ra hết cỡ để khoe 'to bằng này!' → TO LỚN. • 十 [THẬP] Mười — On: ジュウ / Kun: とお (2 nét) Từ ghép: 十日 (とおか) ngày 10 ・ 二十歳 (はたち) 20 tuổi ・ 十分 (じゅっぷん) 10 phút Mẹo: Dấu cộng = đủ mười ngón tay của hai bàn tay chắp ngang dọc. | C30: 20 | D30: Chưa học
A31: 文 Ngữ pháp | B31: Minna bài 2 (2/2) — これ・それ・あれ — Chỉ đồ vật • N1 の N2 (chất liệu, chủ đề) (N2 làm bằng / nói về N1.) Ví dụ: これは 日本語の 本です。 = Đây là sách tiếng Nhật. • 〜は 〜ですか、〜ですか (Câu hỏi lựa chọn: A hay B?) Ví dụ: これは ペンですか、えんぴつですか。 = Cái này là bút bi hay bút chì? → Làm 練習A của bài 2 trong sách, mỗi mẫu tự đặt 3 câu. | C31: 25 | D31: Chưa học
A32: 語 Từ vựng | B32: Từ mới Minna bài 2: • とけい（時計） = Đồng hồ Mẹo: THỜI KẾ = dụng cụ đo thời gian. 時 (thời) vừa học. • かさ（傘） = Ô, dù Mẹo: Kanji 傘 nhìn đúng như cái ô đang xòe ra có nan. • かばん = Cặp, túi xách Mẹo: KA-BAN nghe như 'cà bần' — cái túi đeo lủng lẳng. • テレビ = Ti vi Mẹo: Từ 'television'. Katakana rút gọn tiếng Anh. • ラジオ = Radio Mẹo: Đọc thẳng từ 'radio'. • えんぴつ（鉛筆） = Bút chì Mẹo: DIÊN BÚT = bút bằng chì. 筆 (bút) là bộ 竹 (tre) + 聿. • ボールペン = Bút bi Mẹo: 'Ball pen' — bút có viên bi ở đầu. → Đối chiếu thêm với mục 語彙 của bài 2 trong sách để bổ sung. | C32: 20 | D32: Chưa học
A33: 耳 Nghe | B33: Làm 聴解 (phần nghe) trong sách bài tập Minna 標準問題集 của bài đang học. | C33: 20 | D33: Chưa học
A35: NGÀY 19 · Tuần 3 · Minna Bài 3 (1/2) · ここ・そこ・あそこ — Chỉ nơi chốn 〔100 phút · 6 việc〕
A36: ◐ Khởi động | B36: Ôn nhanh nội dung hôm qua: đọc lại Kanji và mẫu ngữ pháp cũ, không nhìn đáp án. | C36: 5 | D36: Chưa học
A37: 部 Bộ thủ | B37: Bộ 木 (き / きへん) = Cây, gỗ Mẹo nhớ: Thân cây có cành và rễ Kanji chứa bộ này: 木・本・校・東 | C37: 10 | D37: Chưa học
A38: 漢 Kanji | B38: Học 2 chữ. Mỗi chữ viết tay 10 lần đúng thứ tự nét. • 二 [NHỊ] Hai — On: ニ / Kun: ふた(つ) (2 nét) Từ ghép: 二つ (ふたつ) hai cái ・ 二人 (ふたり) hai người ・ 二月 (にがつ) tháng Hai Mẹo: Hai nét ngang = số 2. Nét trên ngắn, nét dưới dài — viết ngược là sai. • 本 [BẢN / BỔN] Sách, gốc, quyển — On: ホン / Kun: もと (5 nét) Từ ghép: 本 (ほん) sách ・ 日本 (にほん) Nhật Bản ・ 本屋 (ほんや) hiệu sách Mẹo: Chữ 木 (cây) thêm một gạch ở gốc rễ = GỐC của cây. Gốc → nguồn gốc → sách (nguồn tri thức). | C38: 20 | D38: Chưa học
A39: 文 Ngữ pháp | B39: Minna bài 3 (1/2) — ここ・そこ・あそこ — Chỉ nơi chốn • ここ / そこ / あそこ (Chỗ này / chỗ đó / chỗ kia.) Ví dụ: ここは 教室です。 = Đây là phòng học. • こちら / そちら / あちら (Phía này / phía đó / phía kia. Lịch sự hơn, cũng dùng chỉ người.) Ví dụ: こちらは 田中さんです。 = Đây là anh Tanaka. • N は 場所 です (N ở chỗ nào đó.) Ví dụ: 電話は 2階です。 = Điện thoại ở tầng 2. → Làm 練習A của bài 3 trong sách, mỗi mẫu tự đặt 3 câu. | C39: 25 | D39: Chưa học
A40: 語 Từ vựng | B40: Từ mới Minna bài 3: • きょうしつ（教室） = Phòng học Mẹo: GIÁO THẤT = phòng để dạy. 室 (thất) = phòng, gặp lại ở 事務室. • しょくどう（食堂） = Nhà ăn, căng tin Mẹo: THỰC ĐƯỜNG = nơi để ăn. 食 (thực) = ăn. • じむしょ（事務所） = Văn phòng Mẹo: SỰ VỤ SỞ = nơi xử lý công việc. • かいぎしつ（会議室） = Phòng họp Mẹo: HỘI NGHỊ THẤT = phòng hội nghị. • うけつけ（受付） = Quầy lễ tân Mẹo: THỤ PHÓ = nơi TIẾP NHẬN (受 = nhận) khách. • トイレ / おてあらい（お手洗い） = Nhà vệ sinh Mẹo: お手洗い = 'chỗ RỬA TAY' (手 tay + 洗 rửa) — cách nói lịch sự. • かいだん（階段） = Cầu thang Mẹo: GIAI ĐOẠN = từng bậc từng bậc. 階 (giai) = tầng. → Đối chiếu thêm với mục 語彙 của bài 3 trong sách để bổ sung. | C40: 20 | D40: Chưa học
A41: 読 Đọc | B41: Vào NHK News Web Easy đọc 1 bài. Gạch chân từ mới, chép 3 câu vào sổ. | C41: 20 | D41: Chưa học
A43: NGÀY 20 · Tuần 3 · Minna Bài 3 (2/2) · ここ・そこ・あそこ — Chỉ nơi chốn 〔100 phút · 6 việc〕
A44: ◐ Khởi động | B44: Ôn nhanh nội dung hôm qua: đọc lại Kanji và mẫu ngữ pháp cũ, không nhìn đáp án. | C44: 5 | D44: Chưa học
A45: 部 Bộ thủ | B45: Bộ 水 / 氵 (みず / さんずい) = Nước, chất lỏng Mẹo nhớ: 氵 ba giọt nước bên trái Kanji chứa bộ này: 水・海・池・酒 | C45: 10 | D45: Chưa học
...

Sheet 5. Chi tiết N46-77
A1: GIAI ĐOẠN 2B · NGÀY 46–77 · MINNA BÀI 14–25
A2: Mục | B2: Việc cần làm hôm nay | C2: Phút | D2: Trạng thái | E2: Ghi chú
A3: NGÀY 46 · Tuần 7 · Minna Bài 14 (2/3) · Thể て & Yêu cầu 〔100 phút · 6 việc〕
A4: ◐ Khởi động | B4: Ôn nhanh nội dung hôm qua: đọc lại Kanji và mẫu ngữ pháp cũ, không nhìn đáp án. | C4: 5 | D4: Chưa học
A5: 部 Bộ thủ | B5: Bộ 小 (しょう) = Nhỏ, ít Mẹo nhớ: Ba chấm bé xíu Kanji chứa bộ này: 小・少 | C5: 10 | D5: Chưa học
A6: 漢 Kanji | B6: Học 2 chữ. Mỗi chữ viết tay 10 lần đúng thứ tự nét. • 北 [BẮC] Hướng bắc — On: ホク / Kun: きた (5 nét) Từ ghép: 北 (きた) hướng bắc ・ 北海道 (ほっかいどう) Hokkaido ・ 東北 (とうほく) vùng Tohoku Mẹo: Hai người quay lưng vào nhau vì trời BẮC quá lạnh, phải dựa lưng sưởi ấm. • 午 [NGỌ] Giữa trưa — On: ゴ / Kun: — (4 nét) Từ ghép: 午前 (ごぜん) buổi sáng ・ 午後 (ごご) buổi chiều ・ 正午 (しょうご) chính ngọ Mẹo: Giống chữ 牛 (con bò) nhưng thiếu một nét. Giờ NGỌ trong 12 con giáp = 11–13h. | C6: 20 | D6: Chưa học
A7: 文 Ngữ pháp | B7: Minna bài 14 (2/3) — Thể て & Yêu cầu • V て います (Đang làm ~ (hành động đang diễn ra).) Ví dụ: 今 雨が 降って います。 = Bây giờ trời đang mưa. → Làm 練習A của bài 14 trong sách, mỗi mẫu tự đặt 3 câu. | C7: 25 | D7: Chưa học
A8: 語 Từ vựng | B8: Từ mới Minna bài 14: • まちます（待ちます） = Đợi Mẹo: 待 có bộ 彳 (bước đi) + 寺 (chùa) → đứng ở chùa mà ĐỢI. • とめます（止めます） = Dừng, đỗ (xe) Mẹo: 止 nhìn như bàn chân đứng yên → DỪNG. • まがります（曲がります） = Rẽ Mẹo: 曲 nhìn như con đường uốn cong → RẼ. • もちます（持ちます） = Cầm, mang Mẹo: 持 có 扌 (tay) → dùng tay CẦM. • てつだいます（手伝います） = Giúp đỡ Mẹo: THỦ TRUYỀN = đưa tay ra giúp. → Đối chiếu thêm với mục 語彙 của bài 14 trong sách để bổ sung. | C8: 20 | D8: Chưa học
A9: 耳 Nghe | B9: Shadowing 15 phút: bật lại 会話 hôm qua, nói đuổi theo băng, không nhìn script. | C9: 20 | D9: Chưa học
A11: NGÀY 47 · Tuần 7 · Minna Bài 14 (3/3) · Thể て & Yêu cầu 〔100 phút · 6 việc〕
A12: ◐ Khởi động | B12: Ôn nhanh nội dung hôm qua: đọc lại Kanji và mẫu ngữ pháp cũ, không nhìn đáp án. | C12: 5 | D12: Chưa học
A13: 部 Bộ thủ | B13: Bộ 宀 (うかんむり) = Mái nhà, nơi ở Mẹo nhớ: Nóc nhà úp lên trên chữ Kanji chứa bộ này: 安・家・室・宿 | C13: 10 | D13: Chưa học
A14: 漢 Kanji | B14: Học 2 chữ. Mỗi chữ viết tay 10 lần đúng thứ tự nét. • 百 [BÁCH] Trăm — On: ヒャク / Kun: — (6 nét) Từ ghép: 百 (ひゃく) một trăm ・ 三百 (さんびゃく) ba trăm ・ 八百屋 (やおや) hàng rau Mẹo: Số 一 (một) đặt trên 白 (trắng) = một trang giấy trắng ghi đủ 100 gạch. • 書 [THƯ] Viết — On: ショ / Kun: か(く) (10 nét) Từ ghép: 書きます (かきます) viết ・ 辞書 (じしょ) từ điển ・ 図書館 (としょかん) thư viện Mẹo: Phần trên là bàn tay cầm bút, phần dưới là 日 (tờ giấy) = tay cầm bút VIẾT lên giấy. | C14: 20 | D14: Chưa học
A15: 文 Ngữ pháp | B15: Minna bài 14 (3/3) — Thể て & Yêu cầu • V ましょうか (Để tôi ~ nhé? Đề nghị giúp đỡ.) Ví dụ: 荷物を 持ちましょうか。 = Để tôi xách hành lý cho nhé? → Làm 練習A của bài 14 trong sách, mỗi mẫu tự đặt 3 câu. | C15: 25 | D15: Chưa học
A16: 語 Từ vựng | B16: Từ mới Minna bài 14: • よびます（呼びます） = Gọi (người) Mẹo: 呼 có 口 (miệng) → dùng miệng GỌI. • みせます（見せます） = Cho xem Mẹo: 見 (nhìn) → làm cho người khác nhìn = CHO XEM. • ゆっくり = Từ từ, thong thả Mẹo: ゆっくり 話して ください = xin nói chậm lại. • すぐ = Ngay lập tức Mẹo: すぐ 行きます = tôi đi ngay đây. → Đối chiếu thêm với mục 語彙 của bài 14 trong sách để bổ sung. | C16: 20 | D16: Chưa học
A17: 読 Đọc | B17: Làm phần 読み物 hoặc 練習C của bài đang học. Đọc to thành tiếng ít nhất 1 lượt. | C17: 20 | D17: Chưa học
A19: NGÀY 48 · Tuần 7 · Minna Bài 15 (1/2) · Cho phép & Cấm đoán 〔100 phút · 6 việc〕
A20: ◐ Khởi động | B20: Ôn nhanh nội dung hôm qua: đọc lại Kanji và mẫu ngữ pháp cũ, không nhìn đáp án. | C20: 5 | D20: Chưa học
A21: 部 Bộ thủ | B21: Bộ 艹 (くさかんむり) = Cỏ, thực vật Mẹo nhớ: Hai chồi cỏ mọc trên đầu chữ Kanji chứa bộ này: 花・茶・草・薬 | C21: 10 | D21: Chưa học
A22: 漢 Kanji | B22: Học 2 chữ. Mỗi chữ viết tay 10 lần đúng thứ tự nét. • 先 [TIÊN] Trước, đi đầu — On: セン / Kun: さき (6 nét) Từ ghép: 先生 (せんせい) giáo viên ・ 先月 (せんげつ) tháng trước ・ 先 (さき) phía trước Mẹo: 先生 = TIÊN SINH = người SINH RA TRƯỚC, đi trước ta → thầy cô. Nhớ theo âm Hán Việt là chắc nhất. • 名 [DANH] Tên, nổi tiếng — On: メイ / Kun: な (6 nét) Từ ghép: 名前 (なまえ) tên ・ 有名 (ゆうめい) nổi tiếng ・ 名刺 (めいし) danh thiếp Mẹo: 夕 (chiều tối) + 口 (miệng) = trời tối không nhìn rõ mặt, phải xưng TÊN bằng miệng. | C22: 20 | D22: Chưa học
A23: 文 Ngữ pháp | B23: Minna bài 15 (1/2) — Cho phép & Cấm đoán • V て も いいです (Được phép làm ~.) Ví dụ: 写真を 撮っても いいですか。 = Tôi chụp ảnh có được không? • V て は いけません (Không được làm ~ (cấm đoán).) Ví dụ: ここで たばこを 吸っては いけません。 = Không được hút thuốc ở đây. → Làm 練習A của bài 15 trong sách, mỗi mẫu tự đặt 3 câu. | C23: 25 | D23: Chưa học
A24: 語 Từ vựng | B24: Từ mới Minna bài 15: • すみます（住みます） = Sống, cư trú Mẹo: 住 = 亻 (người) + 主 (chủ) → người làm chủ chỗ ở. Luôn dùng thể 住んで います. • つかいます（使います） = Dùng, sử dụng Mẹo: 使 = 亻 (người) + 吏 → sai người làm việc → SỬ DỤNG. • しります（知ります） = Biết Mẹo: 知 = 矢 (mũi tên) + 口 → lời nói bắn thẳng như tên = BIẾT rõ. • つくります（作ります） = Làm, chế tạo Mẹo: 作 = 亻 (người) + 乍 → người tạo ra vật. • うります（売ります） = Bán Mẹo: 売 nhìn giống 買 lộn ngược nghĩa. 売り buôn — 買い mua. • しっています（知っています） = Biết Mẹo: Phủ định là 知りません, KHÔNG phải 知っていません. Đây là bẫy đề thi. • けんきゅうしゃ（研究者） = Nhà nghiên cứu Mẹo: NGHIÊN CỨU GIẢ. 者 (giả) = người, đã gặp ở 医者. → Đối chiếu thêm với mục 語彙 của bài 15 trong sách để bổ sung. | C24: 20 | D24: Chưa học
A25: 耳 Nghe | B25: Làm 聴解 (phần nghe) trong sách bài tập Minna 標準問題集 của bài đang học. | C25: 20 | D25: Chưa học
A27: NGÀY 49 · Tuần 7 · Minna Ôn bài 13–14 · Ôn tập tuần 7 — Minna bài 13–14 〔105 phút · 5 việc〕
A28: 漢 Kanji | B28: Viết lại toàn bộ Kanji đã học trong tuần: che nghĩa → đọc chữ, che chữ → viết lại. Lọc sheet '9. Kanji 103' theo cột Ngày học để biết chính xác chữ nào. | C28: 25 | D28: Chưa học
A29: 部 Bộ thủ | B29: Ôn 6 bộ thủ của tuần: nhìn bộ nói nghĩa, kể 1 Kanji chứa bộ đó. | C29: 10 | D29: Chưa học
A30: 文 Ngữ pháp | B30: Làm phần 練習B và 練習C trong Minna bài 13–14. Sau đó tự đặt 5 câu mới. | C30: 25 | D30: Chưa học
A31: 語 Từ vựng | B31: Kiểm tra lại toàn bộ từ vựng Minna bài 13–14. Từ nào quên đánh dấu 'Đang học'. | C31: 20 | D31: Chưa học
A32: 耳読 Nghe + Đọc | B32: Làm phần 問題 (nghe + đọc) cuối mỗi bài trong Minna bài 13–14. Ghi lỗi sai vào cột Ghi chú. | C32: 25 | D32: Chưa học
A34: NGÀY 50 · Tuần 8 · Minna Bài 15 (2/2) · Cho phép & Cấm đoán 〔100 phút · 6 việc〕
A35: ◐ Khởi động | B35: Ôn nhanh nội dung hôm qua: đọc lại Kanji và mẫu ngữ pháp cũ, không nhìn đáp án. | C35: 5 | D35: Chưa học
A36: 部 Bộ thủ | B36: Bộ 辶 (しんにょう) = Di chuyển, đường đi Mẹo nhớ: Ngã tư và bàn chân bước — bao bên trái và dưới Kanji chứa bộ này: 道・週・近・通 | C36: 10 | D36: Chưa học
A37: 漢 Kanji | B37: Học 2 chữ. Mỗi chữ viết tay 10 lần đúng thứ tự nét. • 川 [XUYÊN] Sông — On: セン / Kun: かわ (3 nét) Từ ghép: 川 (かわ) sông ・ 川口 (かわぐち) cửa sông ・ 小川 (おがわ) suối nhỏ Mẹo: Ba đường nước chảy song song = dòng SÔNG nhìn từ trên cao. • 千 [THIÊN] Nghìn — On: セン / Kun: ち (3 nét) Từ ghép: 千 (せん) một nghìn ・ 千円 (せんえん) 1000 yên ・ 三千 (さんぜん) ba nghìn Mẹo: Chữ 十 (mười) có thêm một nét phẩy trên đầu = mười nhân lên nhiều lần → NGHÌN. | C37: 20 | D37: Chưa học
A38: 文 Ngữ pháp | B38: Minna bài 15 (2/2) — Cho phép & Cấm đoán • V て います (trạng thái) (Diễn tả trạng thái kéo dài, nghề nghiệp, thói quen.) Ví dụ: わたしは 銀行で 働いて います。 = Tôi đang làm việc tại ngân hàng. • 〜を 知って います / 知りません (Biết / không biết. Chú ý: phủ định KHÔNG phải 知って いません.) Ví dụ: 田中さんの 電話番号を 知って いますか。 = Bạn có biết số điện thoại của anh Tanaka không? → Làm 練習A của bài 15 trong sách, mỗi mẫu tự đặt 3 câu. | C38: 25 | D38: Chưa học
A39: 語 Từ vựng | B39: Từ mới Minna bài 15: • こうこう（高校） = Trường cấp 3 Mẹo: CAO HIỆU = trường bậc cao. Rút gọn từ 高等学校. • びょういん（病院） = Bệnh viện Mẹo: BỆNH VIỆN — âm Hán Việt y hệt tiếng Việt. • かぞく（家族） = Gia đình Mẹo: GIA TỘC = người trong nhà. • どくしん（独身） = Độc thân Mẹo: ĐỘC THÂN — âm Hán Việt y hệt. • しゃしん（写真） = Ảnh Mẹo: TẢ CHÂN = ghi lại sự thật. 写真を 撮ります = chụp ảnh. • でんわばんごう（電話番号） = Số điện thoại Mẹo: ĐIỆN THOẠI PHIÊN HIỆU. 番号 (phiên hiệu) = con số thứ tự. • たばこ = Thuốc lá Mẹo: たばこを 吸います — dùng 吸います (hút vào) chứ không dùng 飲みます. → Đối chiếu thêm với mục 語彙 của bài 15 trong sách để bổ sung. | C39: 20 | D39: Chưa học
A40: 耳 Nghe | B40: Xem 15 phút Erin's Challenge hoặc Nihongo no Mori N5, bật phụ đề tiếng Nhật. | C40: 20 | D40: Chưa học
A42: NGÀY 51 · Tuần 8 · Minna Bài 16 (1/2) · Nối câu bằng thể て 〔100 phút · 6 việc〕
A43: ◐ Khởi động | B43: Ôn nhanh nội dung hôm qua: đọc lại Kanji và mẫu ngữ pháp cũ, không nhìn đáp án. | C43: 5 | D43: Chưa học
A44: 部 Bộ thủ | B44: Bộ 彳 (ぎょうにんべん) = Bước đi, hành trình Mẹo nhớ: Ngã ba đường thu nhỏ bên trái Kanji chứa bộ này: 後・待・役 | C44: 10 | D44: Chưa học
A45: 漢 Kanji | B45: Học 2 chữ. Mỗi chữ viết tay 10 lần đúng thứ tự nét. • 道 [ĐẠO] Đường, con đường — On: ドウ / Kun: みち (12 nét) Từ ghép: 道 (みち) con đường ・ 北海道 (ほっかいどう) Hokkaido ・ 柔道 (じゅうどう) judo Mẹo: Bộ 辶 (di chuyển) + 首 (cái đầu) = ngẩng đầu bước đi trên con ĐƯỜNG. • 水 [THỦY] Nước — On: スイ / Kun: みず (4 nét) Từ ghép: 水 (みず) nước ・ 水曜日 (すいようび) thứ Tư ・ 水道 (すいどう) đường ống nước Mẹo: Dòng nước chảy với các tia bắn ra hai bên. | C45: 20 | D45: Chưa học
...

Sheet 6. Chi tiết N78-90
A1: GIAI ĐOẠN 3 · NGÀY 78–90 · TỔNG ÔN & THI THỬ
A2: Mục | B2: Việc cần làm hôm nay | C2: Phút | D2: Trạng thái | E2: Ghi chú
A3: NGÀY 78 · Tuần 12 · Tổng ôn Kanji vòng 1 〔100 phút · 4 việc〕
A4: 漢 Kanji | B4: Chạy hết 103 Kanji: chia 4 lượt × 26 chữ. Che nghĩa đọc chữ, che chữ viết lại. Chữ nào sai đánh dấu ★ ở sheet '9. Kanji 103'. | C4: 35 | D4: Chưa học
A5: 部 Bộ thủ | B5: Ôn 45 bộ thủ: nhìn bộ nói nghĩa, kể 1 Kanji chứa bộ đó. Bộ nào quên viết lại 5 lần. | C5: 15 | D5: Chưa học
A6: 語 Từ vựng | B6: Lọc sheet Từ vựng theo cột Trạng thái, ôn lại mọi từ chưa tick 'Xong'. | C6: 25 | D6: Chưa học
A7: 耳 Nghe | B7: Nghe lại 会話 của Minna bài 1–8, chép chính tả 1 bài. | C7: 25 | D7: Chưa học
A9: NGÀY 79 · Tuần 12 · Tổng ôn trợ từ (Minna bài 1–10) 〔100 phút · 4 việc〕
A10: 漢 Kanji | B10: Viết lại các chữ ★ hôm qua, mỗi chữ 5 lần kèm 1 từ ghép. | C10: 20 | D10: Chưa học
A11: 文 Ngữ pháp | B11: Ôn toàn bộ trợ từ は・が・を・に・で・へ・と・も・や・から・まで. Tự đặt 1 câu cho mỗi trợ từ. | C11: 35 | D11: Chưa học
A12: 語 Từ vựng | B12: Ôn từ vựng Minna bài 1–10 (khoảng 140 từ). | C12: 25 | D12: Chưa học
A13: 読 Đọc | B13: Đọc 2 bài NHK Easy News, gạch chân từ chưa biết. | C13: 20 | D13: Chưa học
A15: NGÀY 80 · Tuần 12 · Tổng ôn tính từ & so sánh (bài 8, 12, 16) 〔100 phút · 4 việc〕
A16: 漢 Kanji | B16: Ôn nhóm Kanji số đếm, thời gian, phương hướng: 一〜十・百・千・万・時・分・半・東西南北・上下左右. | C16: 20 | D16: Chưa học
A17: 文 Ngữ pháp | B17: Ôn chia tính từ い/な ở 4 thể, và より・ほうが・いちばん・どちら. | C17: 35 | D17: Chưa học
A18: 語 Từ vựng | B18: Ôn tính từ theo cặp trái nghĩa: 大きい↔小さい, 安い↔高い, 広い↔狭い, 明るい↔暗い. | C18: 25 | D18: Chưa học
A19: 耳 Nghe | B19: Xem 15 phút Erin's Challenge, trả lời câu hỏi cuối video. | C19: 20 | D19: Chưa học
A21: NGÀY 81 · Tuần 12 · Tổng ôn chia động từ (bài 14, 17, 18, 19) 〔100 phút · 4 việc〕
A22: 漢 Kanji | B22: Ôn nhóm Kanji động từ: 行・見・聞・食・飲・買・読・書・話・来・入・出・立・休. | C22: 20 | D22: Chưa học
A23: 文 Ngữ pháp | B23: Bảng chia tổng hợp: ます → て → ない → 辞書形 → た. Lấy 20 động từ tự chia đủ 5 thể. | C23: 40 | D23: Chưa học
A24: 語 Từ vựng | B24: Ôn từ vựng Minna bài 11–18. | C24: 20 | D24: Chưa học
A25: 読 Đọc | B25: Đọc 3 đoạn dokkai ngắn, bấm giờ 2 phút mỗi bài. | C25: 20 | D25: Chưa học
A27: NGÀY 82 · Tuần 12 · Luyện dạng đề: Chữ Hán – Từ vựng 〔95 phút · 4 việc〕
A28: 📝 Luyện đề | B28: Mondai 1–2: nhìn Kanji chọn cách đọc đúng. 30 câu, bấm giờ 10 phút. | C28: 25 | D28: Chưa học
A29: 📝 Luyện đề | B29: Mondai 3–4: chọn từ điền chỗ trống, chọn câu cùng nghĩa. 30 câu. | C29: 30 | D29: Chưa học
A30: 語 Từ vựng | B30: Ôn cặp từ đồng nghĩa / trái nghĩa hay bị đánh lừa trong đề. | C30: 20 | D30: Chưa học
A31: 耳 Nghe | B31: Nghe 1 đề Choukai phần 1 (課題理解) đầy đủ. | C31: 20 | D31: Chưa học
A33: NGÀY 83 · Tuần 12 · Luyện dạng đề: Ngữ pháp – Đọc hiểu 〔95 phút · 4 việc〕
A34: 漢 Kanji | B34: Vòng 2 các chữ ★. Chữ nào vẫn sai chép vào sổ tay riêng. | C34: 20 | D34: Chưa học
A35: 📝 Luyện đề | B35: Luyện 文の組み立て (sắp xếp câu) 20 câu — dạng mất điểm nhiều nhất. | C35: 30 | D35: Chưa học
A36: 読 Đọc | B36: 1 bài đọc dài + 1 bài 情報検索 (tìm thông tin trong tờ rơi, bảng giờ tàu). | C36: 30 | D36: Chưa học
A37: 語 Từ vựng | B37: Ôn trạng từ tần suất: よく・ときどき・あまり・ぜんぜん・いつも・もう・まだ. | C37: 15 | D37: Chưa học
A39: NGÀY 84 · Tuần 12 · 🎯 ĐỀ THI THỬ SỐ 1 — full, bấm giờ 〔120 phút · 4 việc〕
A40: 📝 Luyện đề | B40: Phần 1: 文字・語彙 (Chữ Hán – Từ vựng) — 25 phút, không tra từ điển. | C40: 25 | D40: Chưa học
A41: 📝 Luyện đề | B41: Phần 2: 文法・読解 (Ngữ pháp – Đọc hiểu) — 50 phút. | C41: 50 | D41: Chưa học
A42: 📝 Luyện đề | B42: Phần 3: 聴解 (Nghe hiểu) — 30 phút, chỉ nghe 1 lần đúng như thi thật. | C42: 30 | D42: Chưa học
A43: ✓ Chấm điểm | B43: Chấm và ghi số câu sai từng phần vào cột Ghi chú. Chuẩn đỗ: tổng ≥ 80/180 và mỗi phần ≥ 19/60. | C43: 15 | D43: Chưa học
A45: NGÀY 85 · Tuần 13 · Chữa đề số 1 〔100 phút · 4 việc〕
A46: 漢 Kanji | B46: Chép mọi Kanji làm sai vào sổ tay, viết mỗi chữ 10 lần. | C46: 25 | D46: Chưa học
A47: 文 Ngữ pháp | B47: Với mỗi câu sai: viết ra LÝ DO vì sao sai, không chỉ khoanh đáp án đúng. | C47: 30 | D47: Chưa học
...

Sheet 7. Bảng chữ cái
A1: BẢNG CHỮ CÁI — 104 Hiragana & 104 Katakana, kèm mẹo nhớ hình dáng
A2: STT | B2: Hiragana | C2: Katakana | D2: Romaji | E2: Ngày học | F2: Trạng thái | G2: Mẹo nhớ hình dáng
A3: 1 | B3: あ | C3: ア | D3: a | E3: 1 | F3: Chưa học | G3: Giống chữ 'a' viết hoa bị gạch chéo — hoặc hình quả táo (Apple) có cuống.
A4: 2 | B4: い | C4: イ | D4: i | E4: 1 | F4: Chưa học | G4: Hai nét dọc song song, giống số 'i' latinh viết đôi.
A5: 3 | B5: う | C5: ウ | D5: u | E5: 1 | F5: Chưa học | G5: Giống chữ 'u' nghiêng — cái mỏ chim đang kêu 'u u'.
A6: 4 | B6: え | C6: エ | D6: e | E6: 1 | F6: Chưa học | G6: Giống con én (é) đang bay, có đuôi xòe.
A7: 5 | B7: お | C7: オ | D7: o | E7: 1 | F7: Chưa học | G7: Giống あ nhưng thêm một chấm — như 'ông' đội mũ.
A8: 6 | B8: か | C8: カ | D8: ka | E8: 1 | F8: Chưa học | G8: Có nét như thanh kiếm (KA-tana) chém xuống.
A9: 7 | B9: き | C9: キ | D9: ki | E9: 1 | F9: Chưa học | G9: Giống chìa khóa (KEY) có hai răng.
A10: 8 | B10: く | C10: ク | D10: ku | E10: 1 | F10: Chưa học | G10: Giống cái mỏ chim khép lại — hoặc dấu ngoặc '<'.
A11: 9 | B11: け | C11: ケ | D11: ke | E11: 1 | F11: Chưa học | G11: Giống chữ 'k' latinh nằm cạnh một nét dọc.
A12: 10 | B12: こ | C12: コ | D12: ko | E12: 1 | F12: Chưa học | G12: Hai nét ngang ngắn — hai con sâu bò nối đuôi.
A13: 11 | B13: さ | C13: サ | D13: sa | E13: 2 | F13: Chưa học | G13: Giống lưỡi câu — 'sa' xuống nước bắt cá.
A14: 12 | B14: し | C14: シ | D14: shi | E14: 2 | F14: Chưa học | G14: Một nét cong duy nhất, như cần câu — dễ nhất bảng.
... A106: 104 | B106: ぴょ | C106: ピョ | D106: pyo | E106: 6 | F106: Chưa học | G106: Âm ghép: chữ hàng い + や/ゆ/よ viết nhỏ. Đọc liền thành một âm.

Sheet 8. Bộ thủ 45
A1: 45 BỘ THỦ QUAN TRỌNG — mảnh ghép tạo nên Kanji, học 1 bộ mỗi ngày
A2: Mọi chữ có bộ 言 đều liên quan đến lời nói (話 nói chuyện, 語 ngôn ngữ, 読 đọc). Mọi chữ có bộ 氵 đều liên quan đến nước (海 biển, 酒 rượu, 洗 rửa). Nắm 45 bộ này là bạn đoán được nghĩa của chữ chưa từng gặp.
A3: STT | B3: Bộ thủ | C3: Tên tiếng Nhật | D3: Nghĩa | E3: Kanji chứa bộ này | F3: Mẹo nhớ | G3: Ngày học | H3: Trạng thái
A4: 1 | B4: 人 / 亻 | C4: ひと / にんべん | D4: Người | E4: 人・休・何・今 | F4: 亻 đứng bên trái = dáng người đứng nghiêng | G4: 15 | H4: Chưa học
A5: 2 | B5: 口 | C5: くち | D5: Miệng, cái lỗ | E5: 口・名・右・古 | F5: Ô vuông nhỏ = cái miệng đang mở | G5: 16 | H5: Chưa học
A6: 3 | B6: 日 | C6: ひ / にちへん | D6: Mặt trời, ngày | E6: 日・時・明・早 | F6: Ô vuông có gạch giữa = mặt trời | G6: 17 | H6: Chưa học
A7: 4 | B7: 月 | C7: つき / にくづき | D7: Mặt trăng, tháng, thân thể | E7: 月・前・服 | F7: Trăng khuyết; khi chỉ cơ thể đọc là にくづき | G7: 18 | H7: Chưa học
A8: 5 | B8: 木 | C8: き / きへん | D8: Cây, gỗ | E8: 木・本・校・東 | F8: Thân cây có cành và rễ | G8: 19 | H8: Chưa học
A9: 6 | B9: 水 / 氵 | C9: みず / さんずい | D9: Nước, chất lỏng | E9: 水・海・池・酒 | F9: 氵 ba giọt nước bên trái | G9: 20 | H9: Chưa học
A10: 7 | B10: 火 / 灬 | C10: ひ / れんが | D10: Lửa, nhiệt | E10: 火・点・無・焼 | F10: 灬 bốn chấm dưới = ngọn lửa cháy | G10: 22 | H10: Chưa học
A11: 8 | B11: 土 | C11: つち / つちへん | D11: Đất, nơi chốn | E11: 土・地・場・在 | F11: Chữ thập trên nền đất | G11: 23 | H11: Chưa học
A12: 9 | B12: 金 | C12: かね / かねへん | D12: Kim loại, tiền | E12: 金・銀・鉄・鏡 | F12: Mái nhà che kho báu chôn dưới đất | G12: 24 | H12: Chưa học
A13: 10 | B13: 女 | C13: おんな / おんなへん | D13: Phụ nữ, nữ giới | E13: 女・安・好・姉 | F13: Dáng người phụ nữ đang quỳ | G13: 25 | H13: Chưa học
A14: 11 | B14: 子 | C14: こ / こへん | D14: Con, trẻ nhỏ | E14: 子・学・字・孫 | F14: Em bé quấn tã dang tay | G14: 26 | H14: Chưa học
A15: 12 | B15: 心 / 忄 | C15: こころ / りっしんべん | D15: Trái tim, cảm xúc | E15: 心・思・急・忙 | F15: 忄 là trái tim dựng đứng bên trái | G15: 27 | H15: Chưa học
... A48: 45 | B48: 尸 | C48: しかばね | D48: Mái, thân người nằm | E48: 屋・局・屋 | F48: Người nằm nghiêng / mái che | G48: 66 | H48: Chưa học

Sheet 9. Kanji 103
A1: 103 KANJI N5 — âm Hán Việt, âm On/Kun, số nét, từ ghép và mẹo nhớ
A2: STT | B2: Kanji | C2: Hán Việt | D2: Nghĩa | E2: Âm On (音) | F2: Âm Kun (訓) | G2: Nét | H2: Từ ghép thường gặp | I2: Mẹo nhớ | J2: Ngày học | K2: Trạng thái | L2: ★
A3: 1 | B3: 日 | C3: NHẬT | D3: Ngày, mặt trời | E3: ニチ・ジツ | F3: ひ・か | G3: 4 | H3: 日本 (にほん) Nhật Bản ・ 今日 (きょう) hôm nay ・ 毎日 (まいにち) hằng ngày | I3: Ô vuông có một gạch ở giữa = mặt trời có chấm đen. Mặt trời mọc một lần → một NGÀY. | J3: 15 | K3: Chưa học
A4: 2 | B4: 一 | C4: NHẤT | D4: Một | E4: イチ・イツ | F4: ひと(つ) | G4: 1 | H4: 一つ (ひとつ) một cái ・ 一人 (ひとり) một người ・ 一月 (いちがつ) tháng Một | I4: Một nét ngang = số 1. Dễ nhất trong 103 chữ, nhưng chú ý 一人 đọc bất quy tắc là ひとり. | J4: 15 | K4: Chưa học
A5: 3 | B5: 国 | C5: QUỐC | D5: Đất nước | E5: コク | F5: くに | G5: 8 | H5: 外国 (がいこく) nước ngoài ・ 国語 (こくご) quốc ngữ ・ 中国 (ちゅうごく) Trung Quốc | I5: Bộ 囗 (vòng vây, biên giới) bao lấy 玉 (ngọc quý) = lãnh thổ có biên giới bảo vệ báu vật → QUỐC GIA. | J5: 16 | K5: Chưa học
A6: 4 | B6: 会 | C6: HỘI | D6: Gặp gỡ, hội họp | E6: カイ | F6: あ(う) | G6: 6 | H6: 会社 (かいしゃ) công ty ・ 会います (あいます) gặp ・ 会話 (かいわ) hội thoại | I6: Mái nhà 人 che bên trên, nhiều người tụ lại bên dưới = cuộc HỘI HỌP. | J6: 16 | K6: Chưa học
A7: 5 | B7: 人 | C7: NHÂN | D7: Người | E7: ジン・ニン | F7: ひと | G7: 2 | H7: 日本人 (にほんじん) người Nhật ・ 一人 (ひとり) một người ・ 人口 (じんこう) dân số | I7: Hai nét như hai chân đang bước = dáng NGƯỜI đi. Đuôi 〜人 gắn tên nước = người nước đó. | J7: 17 | K7: Chưa học
A8: 6 | B8: 年 | C8: NIÊN | D8: Năm | E8: ネン | F8: とし | G8: 6 | H8: 今年 (ことし) năm nay ・ 去年 (きょねん) năm ngoái ・ 一年 (いちねん) một năm | I8: Hình cây lúa trĩu hạt. Lúa chín một vụ = trôi qua một NĂM. | J8: 17 | K8: Chưa học
A9: 7 | B9: 大 | C9: ĐẠI | D9: To, lớn | E9: ダイ・タイ | F9: おお(きい) | G9: 3 | H9: 大学 (だいがく) đại học ・ 大きい (おおきい) to ・ 大人 (おとな) người lớn | I9: Người 人 dang rộng hai tay ra hết cỡ để khoe 'to bằng này!' → TO LỚN. | J9: 18 | K9: Chưa học
A10: 8 | B10: 十 | C10: THẬP | D10: Mười | E10: ジュウ | F10: とお | G10: 2 | H10: 十日 (とおか) ngày 10 ・ 二十歳 (はたち) 20 tuổi ・ 十分 (じゅっぷん) 10 phút | I10: Dấu cộng = đủ mười ngón tay của hai bàn tay chắp ngang dọc. | J10: 18 | K10: Chưa học
A11: 9 | B11: 二 | C11: NHỊ | D11: Hai | E11: ニ | F11: ふた(つ) | G11: 2 | H11: 二つ (ふたつ) hai cái ・ 二人 (ふたり) hai người ・ 二月 (にがつ) tháng Hai | I11: Hai nét ngang = số 2. Nét trên ngắn, nét dưới dài — viết ngược là sai. | J11: 19 | K11: Chưa học
A12: 10 | B12: 本 | C12: BẢN / BỔN | D12: Sách, gốc, quyển | E12: ホン | F12: もと | G12: 5 | H12: 本 (ほん) sách ・ 日本 (にほん) Nhật Bản ・ 本屋 (ほんや) hiệu sách | I12: Chữ 木 (cây) thêm một gạch ở gốc rễ = GỐC của cây. Gốc → nguồn gốc → sách (nguồn tri thức). | J12: 19 | K12: Chưa học
A13: 11 | B13: 中 | C13: TRUNG | D13: Ở giữa, bên trong | E13: チュウ | F13: なか | G13: 4 | H13: 中国 (ちゅうごく) Trung Quốc ・ 中 (なか) bên trong ・ 一日中 (いちにちじゅう) suốt cả ngày | I13: Một mũi tên xuyên đúng TÂM của ô vuông = ở GIỮA. | J13: 20 | K13: Chưa học
A14: 12 | B14: 長 | C14: TRƯỜNG / TRƯỞNG | D14: Dài, người đứng đầu | E14: チョウ | F14: なが(い) | G14: 8 | H14: 長い (ながい) dài ・ 社長 (しゃちょう) giám đốc ・ 校長 (こうちょう) hiệu trưởng | I14: Hình một ông cụ tóc DÀI chống gậy. Tóc dài → sống lâu → bậc TRƯỞNG bối. | J14: 20 | K14: Chưa học
... A48: 46 | B48: 来 | C48: LAI | D48: Đến, tới | E48: ライ | F48: く(る) | G48: 7 | H48: 来ます (きます) đến ・ 来年 (らいねん) năm sau ・ 来週 (らいしゅう) tuần sau | I48: Hình cây lúa chín. Mùa gặt ĐẾN. Chú ý chia bất quy tắc: 来る→来ます (きます)→来ない (こない). | J48: 40 | K48: Chưa học
A49: 47 | B49: 気 | C49: KHÍ | D49: Khí, tinh thần, tâm trạng | E49: キ・ケ | G49: 6 | H49: 元気 (げんき) khỏe ・ 天気 (てんき) thời tiết ・ 電気 (でんき) điện | I49: Hơi nước bốc lên từ nồi cơm = KHÍ. Khí trong người = tinh thần, khí ngoài trời = thời tiết. | J49: 41 | K49: Chưa học
A50: 48 | B50: 小 | C50: TIỂU | D50: Nhỏ | E50: ショウ | F50: ちい(さい)・こ | G50: 3 | H50: 小さい (ちいさい) nhỏ ・ 小学校 (しょうがっこう) trường tiểu học ・ 小説 (しょうせつ) tiểu thuyết | I50: Ba chấm bé xíu chụm lại. Ngược với 大. | J50: 41 | K50: Chưa học
A51: 49 | B51: 七 | C51: THẤT | D51: Bảy | E51: シチ | F51: なな(つ) | G51: 2 | H51: 七つ (ななつ) bảy cái ・ 七月 (しちがつ) tháng Bảy ・ 七時 (しちじ) bảy giờ | I51: Giống số 7 viết ngược. Đọc là なな hoặc しち — trong đề thi hay hỏi 七時 (しちじ). | J51: 43 | K51: Chưa học
A52: 50 | B52: 山 | C52: SƠN | D52: Núi | E52: サン | F52: やま | G52: 3 | H52: 山 (やま) núi ・ 富士山 (ふじさん) núi Phú Sĩ ・ 火山 (かざん) núi lửa | I52: Ba đỉnh NÚI nhô lên khỏi mặt đất, đỉnh giữa cao nhất. | J52: 43 | K52: Chưa học
A53: 51 | B53: 話 | C53: THOẠI | D53: Nói chuyện, câu chuyện | E53: ワ | F53: はな(す)・はなし | G53: 13 | H53: 話します (はなします) nói ・ 電話 (でんわ) điện thoại ・ 会話 (かいわ) hội thoại | I53: 言 (lời nói) + 舌 (cái lưỡi) = dùng lưỡi để phát ra lời → NÓI CHUYỆN. | J53: 44 | K53: Chưa học
A54: 52 | B54: 多 | C54: ĐA | D54: Nhiều | E54: タ | F54: おお(い) | G54: 6 | H54: 多い (おおい) nhiều ・ 多分 (たぶん) có lẽ ・ 多数 (たすう) đa số | I54: Hai chữ 夕 (buổi tối) chồng lên nhau = hết tối này đến tối khác, NHIỀU lắm. | J54: 44 | K54: Chưa học
A55: 53 | B55: 安 | C55: AN | D55: Rẻ, yên tâm | E55: アン | F55: やす(い) | G55: 6 | H55: 安い (やすい) rẻ ・ 安心 (あんしん) yên tâm ・ 安全 (あんぜん) an toàn | I55: Bộ 宀 (mái nhà) che chở 女 (người phụ nữ) = ở trong nhà thì AN toàn, yên tâm. Yên tâm mua → giá RẺ. | J55: 45 | K55: Chưa học
A56: 54 | B56: 女 | C56: NỮ | D56: Nữ, phụ nữ | E56: ジョ | F56: おんな | G56: 3 | H56: 女の人 (おんなのひと) phụ nữ ・ 女子 (じょし) nữ giới ・ 彼女 (かのじょ) cô ấy | I56: Dáng người phụ nữ đang quỳ, hai tay đặt trước gối. | J56: 45 | K56: Chưa học
A57: 55 | B57: 北 | C57: BẮC | D57: Hướng bắc | E57: ホク | F57: きた | G57: 5 | H57: 北 (きた) hướng bắc ・ 北海道 (ほっかいどう) Hokkaido ・ 東北 (とうほく) vùng Tohoku | I57: Hai người quay lưng vào nhau vì trời BẮC quá lạnh, phải dựa lưng sưởi ấm. | J57: 46 | K57: Chưa học
A58: 56 | B58: 午 | C58: NGỌ | D58: Giữa trưa | E58: ゴ | G58: 4 | H58: 午前 (ごぜん) buổi sáng ・ 午後 (ごご) buổi chiều ・ 正午 (しょうご) chính ngọ | I58: Giống chữ 牛 (con bò) nhưng thiếu một nét. Giờ NGỌ trong 12 con giáp = 11–13h. | J58: 46 | K58: Chưa học
A59: 57 | B59: 百 | C59: BÁCH | D59: Trăm | E59: ヒャク | G59: 6 | H59: 百 (ひゃく) một trăm ・ 三百 (さんびゃく) ba trăm ・ 八百屋 (やおや) hàng rau | I59: Số 一 (một) đặt trên 白 (trắng) = một trang giấy trắng ghi đủ 100 gạch. | J59: 47 | K59: Chưa học
A60: 58 | B60: 書 | C60: THƯ | D60: Viết | E60: ショ | F60: か(く) | G60: 10 | H60: 書きます (かきます) viết ・ 辞書 (じしょ) từ điển ・ 図書館 (としょかん) thư viện | I60: Phần trên là bàn tay cầm bút, phần dưới là 日 (tờ giấy) = tay cầm bút VIẾT lên giấy. | J60: 47 | K60: Chưa học
A61: 59 | B61: 先 | C61: TIÊN | D61: Trước, đi đầu | E61: セン | F61: さき | G61: 6 | H61: 先生 (せんせい) giáo viên ・ 先月 (せんげつ) tháng trước ・ 先 (さき) phía trước | I61: 先生 = TIÊN SINH = người SINH RA TRƯỚC, đi trước ta → thầy cô. Nhớ theo âm Hán Việt là chắc nhất. | J61: 48 | K61: Chưa học
A62: 60 | B62: 名 | C62: DANH | D62: Tên, nổi tiếng | E62: メイ | F62: な | G62: 6 | H62: 名前 (なまえ) tên ・ 有名 (ゆうめい) nổi tiếng ・ 名刺 (めいし) danh thiếp | I62: 夕 (chiều tối) + 口 (miệng) = trời tối không nhìn rõ mặt, phải xưng TÊN bằng miệng. | J62: 48 | K62: Chưa học
A63: 61 | B63: 川 | C63: XUYÊN | D63: Sông | E63: セン | F63: かわ | G63: 3 | H63: 川 (かわ) sông ・ 川口 (かわぐち) cửa sông ・ 小川 (おがわ) suối nhỏ | I63: Ba đường nước chảy song song = dòng SÔNG nhìn từ trên cao. | J63: 50 | K63: Chưa học
A64: 62 | B64: 千 | C64: THIÊN | D64: Nghìn | E64: セン | F64: ち | G64: 3 | H64: 千 (せん) một nghìn ・ 千円 (せんえん) 1000 yên ・ 三千 (さんぜん) ba nghìn | I64: Chữ 十 (mười) có thêm một nét phẩy trên đầu = mười nhân lên nhiều lần → NGHÌN. | J64: 50 | K64: Chưa học
A65: 63 | B65: 道 | C65: ĐẠO | D65: Đường, con đường | E65: ドウ | F65: みち | G65: 12 | H65: 道 (みち) con đường ・ 北海道 (ほっかいどう) Hokkaido ・ 柔道 (じゅうどう) judo | I65: Bộ 辶 (di chuyển) + 首 (cái đầu) = ngẩng đầu bước đi trên con ĐƯỜNG. | J65: 51 | K65: Chưa học
A66: 64 | B66: 水 | C66: THỦY | D66: Nước | E66: スイ | F66: みず | G66: 4 | H66: 水 (みず) nước ・ 水曜日 (すいようび) thứ Tư ・ 水道 (すいどう) đường ống nước | I66: Dòng nước chảy với các tia bắn ra hai bên. | J66: 51 | K66: Chưa học
A67: 65 | B67: 半 | C67: BÁN | D67: Một nửa, rưỡi | E67: ハン | F67: なか(ば) | G67: 5 | H67: 半分 (はんぶん) một nửa ・ 三時半 (さんじはん) 3 giờ rưỡi ・ 半年 (はんとし) nửa năm | I67: Chữ 八 (chia đôi) đè lên đầu = cắt vật ra làm hai → MỘT NỬA. | J67: 52 | K67: Chưa học
A68: 66 | B68: 男 | C68: NAM | D68: Nam giới | E68: ダン・ナン | F68: おとこ | G68: 7 | H68: 男の人 (おとこのひと) đàn ông ・ 男子 (だんし) nam giới ・ 長男 (ちょうなん) con trai trưởng | I68: 田 (ruộng) + 力 (sức mạnh) = người dùng sức cày ruộng → ĐÀN ÔNG. | J68: 52 | K68: Chưa học
A69: 67 | B69: 西 | C69: TÂY | D69: Hướng tây | E69: セイ・サイ | F69: にし | G69: 6 | H69: 西 (にし) hướng tây ・ 西口 (にしぐち) cửa tây ・ 関西 (かんさい) vùng Kansai | I69: Hình con chim đậu vào tổ khi mặt trời lặn phía TÂY. | J69: 53 | K69: Chưa học
A70: 68 | B70: 電 | C70: ĐIỆN | D70: Điện | E70: デン | G70: 13 | H70: 電車 (でんしゃ) tàu điện ・ 電話 (でんわ) điện thoại ・ 電気 (でんき) đèn/điện | I70: Bộ 雨 (mưa) + 田 + nét móc = tia sét ngoằn ngoèo trong cơn mưa → ĐIỆN. | J70: 53 | K70: Chưa học
A71: 69 | B71: 口 | C71: KHẨU | D71: Miệng, cửa | E71: コウ | F71: くち | G71: 3 | H71: 口 (くち) miệng ・ 入口 (いりぐち) lối vào ・ 人口 (じんこう) dân số | I71: Ô vuông = cái MIỆNG đang há. Từ nghĩa miệng → cái cửa (nơi ra vào). | J71: 54 | K71: Chưa học
A72: 70 | B72: 少 | C72: THIỂU | D72: Ít | E72: ショウ | F72: すく(ない)・すこ(し) | G72: 4 | H72: 少ない (すくない) ít ・ 少し (すこし) một chút ・ 少々 (しょうしょう) một lát | I72: Chữ 小 (nhỏ) bị gạch mất một nét = nhỏ hơn cả nhỏ → ÍT. | J72: 54 | K72: Chưa học
A73: 71 | B73: 校 | C73: HIỆU | D73: Trường học | E73: コウ | G73: 10 | H73: 学校 (がっこう) trường học ・ 高校 (こうこう) cấp 3 ・ 校長 (こうちょう) hiệu trưởng | I73: 木 (gỗ) + 交 (giao nhau) = ngôi nhà gỗ nơi mọi người GIAO LƯU học tập → TRƯỜNG. | J73: 55 | K73: Chưa học
...

Sheet 10. Ngữ pháp Minna
A1: 112 MẪU NGỮ PHÁP THEO MINNA NO NIHONGO I — mỗi mẫu có câu ví dụ và bản dịch
A2: STT | B2: Mẫu ngữ pháp | C2: Cách dùng | D2: Ví dụ | E2: Dịch nghĩa | F2: Ngày học | G2: Trạng thái
A3: ▌ BÀI 1 · Chào hỏi & Giới thiệu bản thân
A4: 1 | B4: N1 は N2 です | C4: N1 là N2. は đọc là 'wa' khi làm trợ từ chủ đề. | D4: わたしは グエンです。 | E4: Tôi là Nguyễn. | F4: 15 | G4: Chưa học
A5: 2 | B5: N1 は N2 じゃ ありません | C5: N1 không phải là N2. Văn viết dùng では ありません. | D5: わたしは 学生じゃ ありません。 | E5: Tôi không phải là học sinh. | F5: 15 | G5: Chưa học
A6: 3 | B6: N1 は N2 ですか | C6: N1 có phải là N2 không? Thêm か cuối câu là thành câu hỏi. | D6: ミラーさんは アメリカ人ですか。 | E6: Anh Miller là người Mỹ phải không? | F6: 15 | G6: Chưa học
A7: 4 | B7: N も | C7: N cũng. Thay thế vị trí của は. | D7: わたしも ベトナム人です。 | E7: Tôi cũng là người Việt Nam. | F7: 16 | G7: Chưa học
A8: 5 | B8: N1 の N2 | C8: N2 thuộc về / của N1. | D8: わたしは ABCの 社員です。 | E8: Tôi là nhân viên của công ty ABC. | F8: 16 | G8: Chưa học
A9: ▌ BÀI 2 · これ・それ・あれ — Chỉ đồ vật
A10: 6 | B10: これ / それ / あれ | C10: Cái này (gần tôi) / cái đó (gần bạn) / cái kia (xa cả hai). Đứng một mình như danh từ. | D10: これは 本です。 | E10: Cái này là quyển sách. | F10: 17 | G10: Chưa học
A11: 7 | B11: この N / その N / あの N | C11: N này / N đó / N kia. Bắt buộc phải có danh từ đi sau. | D11: この 本は わたしのです。 | E11: Quyển sách này là của tôi. | F11: 17 | G11: Chưa học
A12: 8 | B12: そうです / そうじゃ ありません | C12: Đúng vậy / Không phải vậy. Dùng trả lời câu hỏi có–không. | D12: はい、そうです。 | E12: Vâng, đúng vậy. | F12: 17 | G12: Chưa học
